Workbook

Sheet Übersicht
A1: Jahr | D1: 2026 | P1: 2027 | AD1: 2028
A2: Monat | E2: 46112 | F2: =EOMONTH(E2,1) -> 46142 | G2: =EOMONTH(F2,1) -> 46173 | H2: =EOMONTH(G2,1) -> 46203 | I2: =EOMONTH(H2,1) -> 46234 | J2: =EOMONTH(I2,1) -> 46265 | K2: =EOMONTH(J2,1) -> 46295 | L2: =EOMONTH(K2,1) -> 46326 | M2: =EOMONTH(L2,1) -> 46356 | N2: =EOMONTH(M2,1) -> 46387 | Q2: =EOMONTH(N2,1) -> 46418 | R2: =EOMONTH(Q2,1) -> 46446 | S2: =EOMONTH(R2,1) -> 46477 | T2: =EOMONTH(S2,1) -> 46507 | U2: =EOMONTH(T2,1) -> 46538 | V2: =EOMONTH(U2,1) -> 46568 | W2: =EOMONTH(V2,1) -> 46599 | X2: =EOMONTH(W2,1) -> 46630 | Y2: =EOMONTH(X2,1) -> 46660 | ... AB2: =EOMONTH(AA2,1) -> 46752 | AE2: =EOMONTH(AB2,1) -> 46783 | AF2: =EOMONTH(AE2,1) -> 46812 | AG2: =EOMONTH(AF2,1) -> 46843 | AH2: =EOMONTH(AG2,1) -> 46873 | AI2: =EOMONTH(AH2,1) -> 46904 | AJ2: =EOMONTH(AI2,1) -> 46934 | AK2: =EOMONTH(AJ2,1) -> 46965 | AL2: =EOMONTH(AK2,1) -> 46996 | AM2: =EOMONTH(AL2,1) -> 47026 | ... AP2: =EOMONTH(AO2,1) -> 47118
A4: Revenue | D4: =SUM(E4:N4) -> 7793 | E4: =Umsatz!D3 -> 15 | F4: =Umsatz!E3 -> 30 | G4: =Umsatz!F3 -> 45 | H4: =Umsatz!G3 -> 75 | I4: =Umsatz!H3 -> 335 | J4: =Umsatz!I3 -> 523.5 | K4: =Umsatz!J3 -> 902 | L4: =Umsatz!K3 -> 1380.5 | ... N4: =Umsatz!M3 -> 2584.5 | P4: =SUM(Q4:AB4) -> 115174.5 | Q4: =Umsatz!N3 -> 3295 | R4: =Umsatz!O3 -> 4150.5 | S4: =Umsatz!P3 -> 5049.5 | T4: =Umsatz!Q3 -> 6093.5 | U4: =Umsatz!R3 -> 7281 | V4: =Umsatz!S3 -> 8498.5 | W4: =Umsatz!T3 -> 9729.5 | X4: =Umsatz!U3 -> 11105.5 | ... AB4: =Umsatz!Y3 -> 17562.5 | AD4: =SUM(AE4:AP4) -> 395781.5 | AE4: =Umsatz!Z3 -> 19472.5 | AF4: =Umsatz!AA3 -> 21526 | AG4: =Umsatz!AB3 -> 23623 | AH4: =Umsatz!AC3 -> 25893.5 | AI4: =Umsatz!AD3 -> 28307.5 | AJ4: =Umsatz!AE3 -> 30780 | AK4: =Umsatz!AF3 -> 33511 | AL4: =Umsatz!AG3 -> 36300.5 | ... AP4: =Umsatz!AK3 -> 49100.5
B5: Beratungsumsatz | D5: =SUM(E5:N5) -> 0 | E5: =Umsatz!D43 -> 0 | F5: =Umsatz!E43 -> 0 | G5: =Umsatz!F43 -> 0 | H5: =Umsatz!G43 -> 0 | I5: =Umsatz!H43 -> 0 | J5: =Umsatz!I43 -> 0 | K5: =Umsatz!J43 -> 0 | L5: =Umsatz!K43 -> 0 | ... N5: =Umsatz!M43 -> 0 | P5: =SUM(Q5:AB5) -> 0 | Q5: =Umsatz!N43 -> 0 | R5: =Umsatz!O43 -> 0 | S5: =Umsatz!P43 -> 0 | T5: =Umsatz!Q43 -> 0 | U5: =Umsatz!R43 -> 0 | V5: =Umsatz!S43 -> 0 | W5: =Umsatz!T43 -> 0 | X5: =Umsatz!U43 -> 0 | ... AB5: =Umsatz!Y43 -> 0 | AD5: =SUM(AE5:AP5) -> 0 | AE5: =Umsatz!Z43 -> 0 | AF5: =Umsatz!AA43 -> 0 | AG5: =Umsatz!AB43 -> 0 | AH5: =Umsatz!AC43 -> 0 | AI5: =Umsatz!AD43 -> 0 | AJ5: =Umsatz!AE43 -> 0 | AK5: =Umsatz!AF43 -> 0 | AL5: =Umsatz!AG43 -> 0 | ... AP5: =Umsatz!AK43 -> 0
B7: Digitaler Umsatz
C8: # Neue Produktnutzer | D8: =SUM(E8:N8) -> 2280 | E8: =Umsatz!D9 -> 3 | F8: =Umsatz!E9 -> 6 | G8: =Umsatz!F9 -> 15 | H8: =Umsatz!G9 -> 35 | I8: =Umsatz!H9 -> 76 | J8: =Umsatz!I9 -> 140 | K8: =Umsatz!J9 -> 263 | L8: =Umsatz!K9 -> 395 | ... N8: =Umsatz!M9 -> 782 | P8: =SUM(Q8:AB8) -> 44589 | Q8: =Umsatz!N9 -> 1037 | R8: =Umsatz!O9 -> 1343 | S8: =Umsatz!P9 -> 1700 | T8: =Umsatz!Q9 -> 2110 | U8: =Umsatz!R9 -> 2576 | V8: =Umsatz!S9 -> 3093 | W8: =Umsatz!T9 -> 3656 | X8: =Umsatz!U9 -> 4283 | ... AB8: =Umsatz!Y9 -> 7494 | AD8: =SUM(AE8:AP8) -> 195386 | AE8: =Umsatz!Z9 -> 8490 | AF8: =Umsatz!AA9 -> 9572 | AG8: =Umsatz!AB9 -> 10743 | AH8: =Umsatz!AC9 -> 12008 | AI8: =Umsatz!AD9 -> 13372 | AJ8: =Umsatz!AE9 -> 14840 | AK8: =Umsatz!AF9 -> 16417 | AL8: =Umsatz!AG9 -> 18108 | ... AP8: =Umsatz!AK9 -> 26135
C9: # Total, zahlende Nutzer | D9: =SUM(E9:N9) -> 272 | E9: =Umsatz!D16+Umsatz!D40 -> 1 | F9: =Umsatz!E16+Umsatz!E40 -> 2 | G9: =Umsatz!F16+Umsatz!F40 -> 3 | H9: =Umsatz!G16+Umsatz!G40 -> 5 | I9: =Umsatz!H16+Umsatz!H40 -> 11 | J9: =Umsatz!I16+Umsatz!I40 -> 18 | K9: =Umsatz!J16+Umsatz!J40 -> 32 | L9: =Umsatz!K16+Umsatz!K40 -> 47 | ... N9: =Umsatz!M16+Umsatz!M40 -> 88 | P9: =SUM(Q9:AB9) -> 3966 | Q9: =Umsatz!N16+Umsatz!N40 -> 113 | R9: =Umsatz!O16+Umsatz!O40 -> 142 | S9: =Umsatz!P16+Umsatz!P40 -> 174 | T9: =Umsatz!Q16+Umsatz!Q40 -> 210 | U9: =Umsatz!R16+Umsatz!R40 -> 250 | V9: =Umsatz!S16+Umsatz!S40 -> 292 | W9: =Umsatz!T16+Umsatz!T40 -> 335 | X9: =Umsatz!U16+Umsatz!U40 -> 382 | ... AB9: =Umsatz!Y16+Umsatz!Y40 -> 606 | AD9: =SUM(AE9:AP9) -> 13668 | AE9: =Umsatz!Z16+Umsatz!Z40 -> 672 | AF9: =Umsatz!AA16+Umsatz!AA40 -> 742 | AG9: =Umsatz!AB16+Umsatz!AB40 -> 815 | AH9: =Umsatz!AC16+Umsatz!AC40 -> 894 | AI9: =Umsatz!AD16+Umsatz!AD40 -> 977 | AJ9: =Umsatz!AE16+Umsatz!AE40 -> 1064 | AK9: =Umsatz!AF16+Umsatz!AF40 -> 1157 | AL9: =Umsatz!AG16+Umsatz!AG40 -> 1254 | ... AP9: =Umsatz!AK16+Umsatz!AK40 -> 1696
C10: Standard | D10: =SUM(E10:N10) -> 3393 | E10: =Umsatz!D18 -> 15 | F10: =Umsatz!E18 -> 30 | G10: =Umsatz!F18 -> 45 | H10: =Umsatz!G18 -> 75 | I10: =Umsatz!H18 -> 135 | J10: =Umsatz!I18 -> 223.5 | K10: =Umsatz!J18 -> 402 | L10: =Umsatz!K18 -> 580.5 | ... N10: =Umsatz!M18 -> 1084.5 | P10: =SUM(Q10:AB10) -> 48874.5 | Q10: =Umsatz!N18 -> 1395 | R10: =Umsatz!O18 -> 1750.5 | S10: =Umsatz!P18 -> 2149.5 | T10: =Umsatz!Q18 -> 2593.5 | U10: =Umsatz!R18 -> 3081 | V10: =Umsatz!S18 -> 3598.5 | W10: =Umsatz!T18 -> 4129.5 | X10: =Umsatz!U18 -> 4705.5 | ... AB10: =Umsatz!Y18 -> 7462.5 | AD10: =SUM(AE10:AP10) -> 167881.5 | AE10: =Umsatz!Z18 -> 8272.5 | AF10: =Umsatz!AA18 -> 9126 | AG10: =Umsatz!AB18 -> 10023 | AH10: =Umsatz!AC18 -> 10993.5 | AI10: =Umsatz!AD18 -> 12007.5 | AJ10: =Umsatz!AE18 -> 13080 | AK10: =Umsatz!AF18 -> 14211 | AL10: =Umsatz!AG18 -> 15400.5 | ... AP10: =Umsatz!AK18 -> 20800.5
C11: Premium | D11: =SUM(E11:N11) -> 4400 | E11: =Umsatz!D38 -> 0 | F11: =Umsatz!E38 -> 0 | G11: =Umsatz!F38 -> 0 | H11: =Umsatz!G38 -> 0 | I11: =Umsatz!H38 -> 200 | J11: =Umsatz!I38 -> 300 | K11: =Umsatz!J38 -> 500 | L11: =Umsatz!K38 -> 800 | ... N11: =Umsatz!M38 -> 1500 | P11: =SUM(Q11:AB11) -> 66300 | Q11: =Umsatz!N38 -> 1900 | R11: =Umsatz!O38 -> 2400 | S11: =Umsatz!P38 -> 2900 | T11: =Umsatz!Q38 -> 3500 | U11: =Umsatz!R38 -> 4200 | V11: =Umsatz!S38 -> 4900 | W11: =Umsatz!T38 -> 5600 | X11: =Umsatz!U38 -> 6400 | ... AB11: =Umsatz!Y38 -> 10100 | AD11: =SUM(AE11:AP11) -> 227900 | AE11: =Umsatz!Z38 -> 11200 | AF11: =Umsatz!AA38 -> 12400 | AG11: =Umsatz!AB38 -> 13600 | AH11: =Umsatz!AC38 -> 14900 | AI11: =Umsatz!AD38 -> 16300 | AJ11: =Umsatz!AE38 -> 17700 | AK11: =Umsatz!AF38 -> 19300 | AL11: =Umsatz!AG38 -> 20900 | ... AP11: =Umsatz!AK38 -> 28300
C12: Monatliches Wachstum | E12: n/a | F12: =(F4-E4)/E4 -> 1 | G12: =(G4-F4)/F4 -> 0.5 | H12: =(H4-G4)/G4 -> 0.66666667 | I12: =(I4-H4)/H4 -> 3.4666667 | J12: =(J4-I4)/I4 -> 0.56268657 | K12: =(K4-J4)/J4 -> 0.72301815 | L12: =(L4-K4)/K4 -> 0.5304878 | M12: =(M4-L4)/L4 -> 0.37812387 | N12: =(N4-M4)/M4 -> 0.35847569 | Q12: =(Q4-N4)/N4 -> 0.27490811 | R12: =(R4-Q4)/Q4 -> 0.25963581 | S12: =(S4-R4)/R4 -> 0.21660041 | T12: =(T4-S4)/S4 -> 0.20675314 | U12: =(U4-T4)/T4 -> 0.19487979 | V12: =(V4-U4)/U4 -> 0.16721604 | W12: =(W4-V4)/V4 -> 0.14484909 | X12: =(X4-W4)/W4 -> 0.14142556 | Y12: =(Y4-X4)/X4 -> 0.12781955 | ... AB12: =(AB4-AA4)/AA4 -> 0.11183211 | AE12: =(AE4-AB4)/AB4 -> 0.10875445 | AF12: =(AF4-AE4)/AE4 -> 0.10545641 | AG12: =(AG4-AF4)/AF4 -> 0.097417077 | AH12: =(AH4-AG4)/AG4 -> 0.096113957 | AI12: =(AI4-AH4)/AH4 -> 0.09322803 | AJ12: =(AJ4-AI4)/AI4 -> 0.087344343 | AK12: =(AK4-AJ4)/AJ4 -> 0.088726446 | AL12: =(AL4-AK4)/AK4 -> 0.083241324 | AM12: =(AM4-AL4)/AL4 -> 0.081211003 | ... AP12: =(AP4-AO4)/AO4 -> 0.075621324
A14: Kosten | D14: =SUM(E14:N14) -> -21306.76 | E14: =Kosten!E3 -> -2857.3 | F14: =Kosten!F3 -> -1697.1 | G14: =Kosten!G3 -> -1213.9 | H14: =Kosten!H3 -> -1356.5 | I14: =Kosten!I3 -> -1513.7 | J14: =Kosten!J3 -> -1757.02 | K14: =Kosten!K3 -> -2182.14 | L14: =Kosten!L3 -> -2956.26 | ... N14: =Kosten!N3 -> -3070.54 | P14: =SUM(Q14:AB14) -> -78747.84 | Q14: =Kosten!O3 -> -3447.9 | R14: =Kosten!P3 -> -3874.66 | S14: =Kosten!Q3 -> -5062.34 | T14: =Kosten!R3 -> -5353.42 | U14: =Kosten!S3 -> -5416.42 | V14: =Kosten!T3 -> -5985.02 | W14: =Kosten!U3 -> -6537.94 | X14: =Kosten!V3 -> -7158.26 | ... AB14: =Kosten!Z3 -> -10165.5 | AD14: =SUM(AE14:AP14) -> -206886.08 | AE14: =Kosten!AA3 -> -11237.7 | AF14: =Kosten!AB3 -> -12068.82 | AG14: =Kosten!AC3 -> -13250.86 | AH14: =Kosten!AD3 -> -14457.42 | AI14: =Kosten!AE3 -> -15045.9 | AJ14: =Kosten!AF3 -> -16173.1 | AK14: =Kosten!AG3 -> -17393.02 | AL14: =Kosten!AH3 -> -18651.66 | ... AP14: =Kosten!AL3 -> -24399.66
B16: Variable Kosten | D16: =SUM(E16:N16) -> -4967.76 | E16: =Kosten!E5 -> -10.8 | F16: =Kosten!F5 -> -21.6 | G16: =Kosten!G5 -> -38.4 | H16: =Kosten!H5 -> -82 | I16: =Kosten!I5 -> -219.2 | J16: =Kosten!J5 -> -362.52 | K16: =Kosten!K5 -> -637.64 | L16: =Kosten!L5 -> -911.76 | ... N16: =Kosten!N5 -> -1526.04 | P16: =SUM(Q16:AB16) -> -58992.84 | Q16: =Kosten!O5 -> -1903.4 | R16: =Kosten!P5 -> -2330.16 | S16: =Kosten!Q5 -> -2796.84 | T16: =Kosten!R5 -> -3308.92 | U16: =Kosten!S5 -> -3871.92 | V16: =Kosten!T5 -> -4440.52 | W16: =Kosten!U5 -> -4993.44 | X16: =Kosten!V5 -> -5613.76 | ... AB16: =Kosten!Z5 -> -8621 | AD16: =SUM(AE16:AP16) -> -187231.08 | AE16: =Kosten!AA5 -> -9493.2 | AF16: =Kosten!AB5 -> -10424.32 | AG16: =Kosten!AC5 -> -11385.36 | AH16: =Kosten!AD5 -> -12412.92 | AI16: =Kosten!AE5 -> -13501.4 | AJ16: =Kosten!AF5 -> -14628.6 | AK16: =Kosten!AG5 -> -15848.52 | AL16: =Kosten!AH5 -> -17107.16 | ... AP16: =Kosten!AL5 -> -22855.16
C17: Variable Operative | D17: =SUM(E17:N17) -> -4967.76 | E17: =Kosten!E5 -> -10.8 | F17: =Kosten!F5 -> -21.6 | G17: =Kosten!G5 -> -38.4 | H17: =Kosten!H5 -> -82 | I17: =Kosten!I5 -> -219.2 | J17: =Kosten!J5 -> -362.52 | K17: =Kosten!K5 -> -637.64 | L17: =Kosten!L5 -> -911.76 | ... N17: =Kosten!N5 -> -1526.04 | P17: =SUM(Q17:AB17) -> -58992.84 | Q17: =Kosten!O5 -> -1903.4 | R17: =Kosten!P5 -> -2330.16 | S17: =Kosten!Q5 -> -2796.84 | T17: =Kosten!R5 -> -3308.92 | U17: =Kosten!S5 -> -3871.92 | V17: =Kosten!T5 -> -4440.52 | W17: =Kosten!U5 -> -4993.44 | X17: =Kosten!V5 -> -5613.76 | ... AB17: =Kosten!Z5 -> -8621 | AD17: =SUM(AE17:AP17) -> -187231.08 | AE17: =Kosten!AA5 -> -9493.2 | AF17: =Kosten!AB5 -> -10424.32 | AG17: =Kosten!AC5 -> -11385.36 | AH17: =Kosten!AD5 -> -12412.92 | AI17: =Kosten!AE5 -> -13501.4 | AJ17: =Kosten!AF5 -> -14628.6 | AK17: =Kosten!AG5 -> -15848.52 | AL17: =Kosten!AH5 -> -17107.16 | ... AP17: =Kosten!AL5 -> -22855.16
B19: Fixkosten | D19: =SUM(E19:N19) -> -16339 | E19: =Kosten!E13 -> -2846.5 | F19: =Kosten!F13 -> -1675.5 | G19: =Kosten!G13 -> -1175.5 | H19: =Kosten!H13 -> -1274.5 | I19: =Kosten!I13 -> -1294.5 | J19: =Kosten!J13 -> -1394.5 | K19: =Kosten!K13 -> -1544.5 | L19: =Kosten!L13 -> -2044.5 | ... N19: =Kosten!N13 -> -1544.5 | P19: =SUM(Q19:AB19) -> -19755 | Q19: =Kosten!O13 -> -1544.5 | R19: =Kosten!P13 -> -1544.5 | S19: =Kosten!Q13 -> -2265.5 | T19: =Kosten!R13 -> -2044.5 | U19: =Kosten!S13 -> -1544.5 | V19: =Kosten!T13 -> -1544.5 | W19: =Kosten!U13 -> -1544.5 | X19: =Kosten!V13 -> -1544.5 | ... AB19: =Kosten!Z13 -> -1544.5 | AD19: =SUM(AE19:AP19) -> -19655 | AE19: =Kosten!AA13 -> -1744.5 | AF19: =Kosten!AB13 -> -1644.5 | AG19: =Kosten!AC13 -> -1865.5 | AH19: =Kosten!AD13 -> -2044.5 | AI19: =Kosten!AE13 -> -1544.5 | AJ19: =Kosten!AF13 -> -1544.5 | AK19: =Kosten!AG13 -> -1544.5 | AL19: =Kosten!AH13 -> -1544.5 | ... AP19: =Kosten!AL13 -> -1544.5
C20: =Kosten!B15 -> Produktentwicklung | D20: =SUM(E20:N20) -> -6800 | E20: =Kosten!E15 -> -680 | F20: =Kosten!F15 -> -680 | G20: =Kosten!G15 -> -680 | H20: =Kosten!H15 -> -680 | I20: =Kosten!I15 -> -680 | J20: =Kosten!J15 -> -680 | K20: =Kosten!K15 -> -680 | L20: =Kosten!L15 -> -680 | ... N20: =Kosten!N15 -> -680 | P20: =SUM(Q20:AB20) -> -8160 | Q20: =Kosten!O15 -> -680 | R20: =Kosten!P15 -> -680 | S20: =Kosten!Q15 -> -680 | T20: =Kosten!R15 -> -680 | U20: =Kosten!S15 -> -680 | V20: =Kosten!T15 -> -680 | W20: =Kosten!U15 -> -680 | X20: =Kosten!V15 -> -680 | ... AB20: =Kosten!Z15 -> -680 | AD20: =SUM(AE20:AP20) -> -8160 | AE20: =Kosten!AA15 -> -680 | AF20: =Kosten!AB15 -> -680 | AG20: =Kosten!AC15 -> -680 | AH20: =Kosten!AD15 -> -680 | AI20: =Kosten!AE15 -> -680 | AJ20: =Kosten!AF15 -> -680 | AK20: =Kosten!AG15 -> -680 | AL20: =Kosten!AH15 -> -680 | ... AP20: =Kosten!AL15 -> -680
C21: =Kosten!B48 -> Marketing Kosten | D21: =SUM(E21:N21) -> -2793 | E21: =Kosten!E48 -> -210 | F21: =Kosten!F48 -> -210 | G21: =Kosten!G48 -> -210 | H21: =Kosten!H48 -> -309 | I21: =Kosten!I48 -> -309 | J21: =Kosten!J48 -> -309 | K21: =Kosten!K48 -> -309 | L21: =Kosten!L48 -> -309 | ... N21: =Kosten!N48 -> -309 | P21: =SUM(Q21:AB21) -> -3708 | Q21: =Kosten!O48 -> -309 | R21: =Kosten!P48 -> -309 | S21: =Kosten!Q48 -> -309 | T21: =Kosten!R48 -> -309 | U21: =Kosten!S48 -> -309 | V21: =Kosten!T48 -> -309 | W21: =Kosten!U48 -> -309 | X21: =Kosten!V48 -> -309 | ... AB21: =Kosten!Z48 -> -309 | AD21: =SUM(AE21:AP21) -> -3708 | AE21: =Kosten!AA48 -> -309 | AF21: =Kosten!AB48 -> -309 | AG21: =Kosten!AC48 -> -309 | AH21: =Kosten!AD48 -> -309 | AI21: =Kosten!AE48 -> -309 | AJ21: =Kosten!AF48 -> -309 | AK21: =Kosten!AG48 -> -309 | AL21: =Kosten!AH48 -> -309 | ... AP21: =Kosten!AL48 -> -309
C22: =Kosten!B29 -> Administrative Kosten | D22: =SUM(E22:N22) -> -1419 | E22: =Kosten!E29 -> -81.9 | F22: =Kosten!F29 -> -81.9 | G22: =Kosten!G29 -> -81.9 | H22: =Kosten!H29 -> -81.9 | I22: =Kosten!I29 -> -81.9 | J22: =Kosten!J29 -> -81.9 | K22: =Kosten!K29 -> -231.9 | L22: =Kosten!L29 -> -231.9 | ... N22: =Kosten!N29 -> -231.9 | P22: =SUM(Q22:AB22) -> -4003.8 | Q22: =Kosten!O29 -> -231.9 | R22: =Kosten!P29 -> -231.9 | S22: =Kosten!Q29 -> -952.9 | T22: =Kosten!R29 -> -731.9 | U22: =Kosten!S29 -> -231.9 | V22: =Kosten!T29 -> -231.9 | W22: =Kosten!U29 -> -231.9 | X22: =Kosten!V29 -> -231.9 | ... AB22: =Kosten!Z29 -> -231.9 | AD22: =SUM(AE22:AP22) -> -3903.8 | AE22: =Kosten!AA29 -> -431.9 | AF22: =Kosten!AB29 -> -331.9 | AG22: =Kosten!AC29 -> -552.9 | AH22: =Kosten!AD29 -> -731.9 | AI22: =Kosten!AE29 -> -231.9 | AJ22: =Kosten!AF29 -> -231.9 | AK22: =Kosten!AG29 -> -231.9 | AL22: =Kosten!AH29 -> -231.9 | ... AP22: =Kosten!AL29 -> -231.9
C23: =Kosten!B21 -> IT Infrastruktur | D23: =SUM(E23:N23) -> -2656 | E23: =Kosten!E21 -> -203.6 | F23: =Kosten!F21 -> -203.6 | G23: =Kosten!G21 -> -203.6 | H23: =Kosten!H21 -> -203.6 | I23: =Kosten!I21 -> -223.6 | J23: =Kosten!J21 -> -323.6 | K23: =Kosten!K21 -> -323.6 | L23: =Kosten!L21 -> -323.6 | ... N23: =Kosten!N21 -> -323.6 | P23: =SUM(Q23:AB23) -> -3883.2 | Q23: =Kosten!O21 -> -323.6 | R23: =Kosten!P21 -> -323.6 | S23: =Kosten!Q21 -> -323.6 | T23: =Kosten!R21 -> -323.6 | U23: =Kosten!S21 -> -323.6 | V23: =Kosten!T21 -> -323.6 | W23: =Kosten!U21 -> -323.6 | X23: =Kosten!V21 -> -323.6 | ... AB23: =Kosten!Z21 -> -323.6 | AD23: =SUM(AE23:AP23) -> -3883.2 | AE23: =Kosten!AA21 -> -323.6 | AF23: =Kosten!AB21 -> -323.6 | AG23: =Kosten!AC21 -> -323.6 | AH23: =Kosten!AD21 -> -323.6 | AI23: =Kosten!AE21 -> -323.6 | AJ23: =Kosten!AF21 -> -323.6 | AK23: =Kosten!AG21 -> -323.6 | AL23: =Kosten!AH21 -> -323.6 | ... AP23: =Kosten!AL21 -> -323.6
C24: =Kosten!B39 -> Gründungskosten | D24: =SUM(E24:N24) -> -2671 | E24: =Kosten!E39 -> -1671 | F24: =Kosten!F39 -> -500 | G24: =Kosten!G39 -> 0 | H24: =Kosten!H39 -> 0 | I24: =Kosten!I39 -> 0 | J24: =Kosten!J39 -> 0 | K24: =Kosten!K39 -> 0 | L24: =Kosten!L39 -> -500 | ... N24: =Kosten!N39 -> 0 | Q24: =Kosten!O39 -> 0 | R24: =Kosten!P39 -> 0 | S24: =Kosten!Q39 -> 0 | T24: =Kosten!R39 -> 0 | U24: =Kosten!S39 -> 0 | V24: =Kosten!T39 -> 0 | W24: =Kosten!U39 -> 0 | X24: =Kosten!V39 -> 0 | ... AB24: =Kosten!Z39 -> 0 | AE24: =Kosten!AA39 -> 0 | AF24: =Kosten!AB39 -> 0 | AG24: =Kosten!AC39 -> 0 | AH24: =Kosten!AD39 -> 0 | AI24: =Kosten!AE39 -> 0 | AJ24: =Kosten!AF39 -> 0 | AK24: =Kosten!AG39 -> 0 | AL24: =Kosten!AH39 -> 0 | ... AP24: =Kosten!AL39 -> 0
A26: Finanzierung
B27: Private Einlagen | D27: =SUM(E27:N27) -> 15000 | E27: ='Liquidität'!C7 -> 4000 | F27: ='Liquidität'!D7 -> 2000 | G27: ='Liquidität'!E7 -> 2000 | H27: ='Liquidität'!F7 -> 2000 | I27: ='Liquidität'!G7 -> 2000 | J27: ='Liquidität'!H7 -> 1000 | K27: ='Liquidität'!I7 -> 1000 | L27: ='Liquidität'!J7 -> 1000 | ... N27: ='Liquidität'!L7 -> 0 | P27: =SUM(Q27:AB27) -> 0 | Q27: ='Liquidität'!M7 -> 0 | R27: ='Liquidität'!N7 -> 0 | S27: ='Liquidität'!O7 -> 0 | T27: ='Liquidität'!P7 -> 0 | U27: ='Liquidität'!Q7 -> 0 | V27: ='Liquidität'!R7 -> 0 | W27: ='Liquidität'!S7 -> 0 | X27: ='Liquidität'!T7 -> 0 | ... AB27: ='Liquidität'!X7 -> 0 | AD27: =SUM(AE27:AP27) -> 0 | AE27: ='Liquidität'!Y7 -> 0 | AF27: ='Liquidität'!Z7 -> 0 | AG27: ='Liquidität'!AA7 -> 0 | AH27: ='Liquidität'!AB7 -> 0 | AI27: ='Liquidität'!AC7 -> 0 | AJ27: ='Liquidität'!AD7 -> 0 | AK27: ='Liquidität'!AE7 -> 0 | AL27: ='Liquidität'!AF7 -> 0 | ... AP27: ='Liquidität'!AJ7 -> 0
A29: Entnahmen | D29: =SUM(E29:N29) -> 0 | E29: ='Rentabilität'!C14 -> 0 | F29: ='Rentabilität'!D14 -> 0 | G29: ='Rentabilität'!E14 -> 0 | H29: ='Rentabilität'!F14 -> 0 | I29: ='Rentabilität'!G14 -> 0 | J29: ='Rentabilität'!H14 -> 0 | K29: ='Rentabilität'!I14 -> 0 | L29: ='Rentabilität'!J14 -> 0 | ... N29: ='Rentabilität'!L14 -> 0 | P29: =SUM(Q29:AB29) -> -32561.737 | Q29: ='Rentabilität'!M14 -> 0 | R29: ='Rentabilität'!N14 -> 0 | S29: ='Rentabilität'!O14 -> -592.03158 | T29: ='Rentabilität'!P14 -> -1184.0632 | U29: ='Rentabilität'!Q14 -> -1776.0948 | V29: ='Rentabilität'!R14 -> -2368.1263 | W29: ='Rentabilität'!S14 -> -2960.1579 | X29: ='Rentabilität'!T14 -> -3552.1895 | ... AB29: ='Rentabilität'!X14 -> -5920.3158 | AD29: =SUM(AE29:AP29) -> -83764.953 | AE29: ='Rentabilität'!Y14 -> -6980.4127 | AF29: ='Rentabilität'!Z14 -> -6980.4127 | AG29: ='Rentabilität'!AA14 -> -6980.4127 | AH29: ='Rentabilität'!AB14 -> -6980.4127 | AI29: ='Rentabilität'!AC14 -> -6980.4127 | AJ29: ='Rentabilität'!AD14 -> -6980.4127 | AK29: ='Rentabilität'!AE14 -> -6980.4127 | AL29: ='Rentabilität'!AF14 -> -6980.4127 | ... AP29: ='Rentabilität'!AJ14 -> -6980.4127
B30: Unternehmerlohn | D30: =SUM(E30:N30) -> 0 | E30: ='Rentabilität'!C14 -> 0 | F30: ='Rentabilität'!D14 -> 0 | G30: ='Rentabilität'!E14 -> 0 | H30: ='Rentabilität'!F14 -> 0 | I30: ='Rentabilität'!G14 -> 0 | J30: ='Rentabilität'!H14 -> 0 | K30: ='Rentabilität'!I14 -> 0 | L30: ='Rentabilität'!J14 -> 0 | ... N30: ='Rentabilität'!L14 -> 0 | P30: =SUM(Q30:AB30) -> -32561.737 | Q30: ='Rentabilität'!M14 -> 0 | R30: ='Rentabilität'!N14 -> 0 | S30: ='Rentabilität'!O14 -> -592.03158 | T30: ='Rentabilität'!P14 -> -1184.0632 | U30: ='Rentabilität'!Q14 -> -1776.0948 | V30: ='Rentabilität'!R14 -> -2368.1263 | W30: ='Rentabilität'!S14 -> -2960.1579 | X30: ='Rentabilität'!T14 -> -3552.1895 | ... AB30: ='Rentabilität'!X14 -> -5920.3158 | AD30: =SUM(AE30:AP30) -> -83764.953 | AE30: ='Rentabilität'!Y14 -> -6980.4127 | AF30: ='Rentabilität'!Z14 -> -6980.4127 | AG30: ='Rentabilität'!AA14 -> -6980.4127 | AH30: ='Rentabilität'!AB14 -> -6980.4127 | AI30: ='Rentabilität'!AC14 -> -6980.4127 | AJ30: ='Rentabilität'!AD14 -> -6980.4127 | AK30: ='Rentabilität'!AE14 -> -6980.4127 | AL30: ='Rentabilität'!AF14 -> -6980.4127 | ... AP30: ='Rentabilität'!AJ14 -> -6980.4127
A32: Liquidität Monatsende | D32: n/a | E32: ='Liquidität'!C26 -> 1157.7 | F32: ='Liquidität'!D26 -> 1490.6 | G32: ='Liquidität'!E26 -> 2321.7 | H32: ='Liquidität'!F26 -> 3040.2 | I32: ='Liquidität'!G26 -> 3861.5 | J32: ='Liquidität'!H26 -> 3776.48 | K32: ='Liquidität'!I26 -> 3631.34 | L32: ='Liquidität'!J26 -> 3177.08 | ... N32: ='Liquidität'!L26 -> 2377.24 | P32: n/a | Q32: ='Liquidität'!M26 -> 2575.34 | R32: ='Liquidität'!N26 -> 3161.68 | S32: ='Liquidität'!O26 -> 2975.3084 | T32: ='Liquidität'!P26 -> 2895.8252 | U32: ='Liquidität'!Q26 -> 3443.3105 | V32: ='Liquidität'!R26 -> 3980.1642 | W32: ='Liquidität'!S26 -> 4684.0662 | X32: ='Liquidität'!T26 -> 5632.6167 | ... AB32: ='Liquidität'!X26 -> 12357.663 | AD32: n/a | AE32: ='Liquidität'!Y26 -> 14570.55 | AF32: ='Liquidität'!Z26 -> 18019.317 | AG32: ='Liquidität'!AA26 -> 22545.045 | AH32: ='Liquidität'!AB26 -> 28121.212 | AI32: ='Liquidität'!AC26 -> 35657.899 | AJ32: ='Liquidität'!AD26 -> 44499.386 | AK32: ='Liquidität'!AE26 -> 54959.954 | AL32: ='Liquidität'!AF26 -> 67045.881 | ... AP32: ='Liquidität'!AJ26 -> 133512.63
A34: Rentabilität | D34: =SUM(E34:N34) -> -13513.76 | E34: ='Rentabilität'!C16 -> -2842.3 | F34: ='Rentabilität'!D16 -> -1667.1 | G34: ='Rentabilität'!E16 -> -1168.9 | H34: ='Rentabilität'!F16 -> -1281.5 | I34: ='Rentabilität'!G16 -> -1178.7 | J34: ='Rentabilität'!H16 -> -1233.52 | K34: ='Rentabilität'!I16 -> -1280.14 | L34: ='Rentabilität'!J16 -> -1575.76 | ... N34: ='Rentabilität'!L16 -> -486.04 | P34: =SUM(Q34:AB34) -> 3864.9229 | Q34: ='Rentabilität'!M16 -> -152.9 | R34: ='Rentabilität'!N16 -> 275.84 | S34: ='Rentabilität'!O16 -> -604.87158 | T34: ='Rentabilität'!P16 -> -443.98317 | U34: ='Rentabilität'!Q16 -> 88.485247 | V34: ='Rentabilität'!R16 -> 145.35366 | W34: ='Rentabilität'!S16 -> 231.40208 | X34: ='Rentabilität'!T16 -> 395.05049 | ... AB34: ='Rentabilität'!X16 -> 1476.6842 | AD34: =SUM(AE34:AP34) -> 105130.47 | AE34: ='Rentabilität'!Y16 -> 1254.3873 | AF34: ='Rentabilität'!Z16 -> 2476.7673 | AG34: ='Rentabilität'!AA16 -> 3391.7273 | AH34: ='Rentabilität'!AB16 -> 4455.6673 | AI34: ='Rentabilität'!AC16 -> 6281.1873 | AJ34: ='Rentabilität'!AD16 -> 7626.4873 | AK34: ='Rentabilität'!AE16 -> 9137.5673 | AL34: ='Rentabilität'!AF16 -> 10668.427 | ... AP34: ='Rentabilität'!AJ16 -> 17720.427
A36: Kennzahlen
B38: Marge pro Nutzer (ohne Fixkosten) | D38: =AVERAGE(E38:N38) -> 7.0389925 | E38: =(E4+E16)/E9 -> 4.2 | F38: =(F4+F16)/F9 -> 4.2 | G38: =(G4+G16)/G9 -> 2.2 | H38: =(H4+H16)/H9 -> -1.4 | I38: =(I4+I16)/I9 -> 10.527273 | J38: =(J4+J16)/J9 -> 8.9433333 | K38: =(K4+K16)/K9 -> 8.26125 | L38: =(L4+L16)/L9 -> 9.9731915 | ... N38: =(N4+N16)/N9 -> 12.027955 | P38: =AVERAGE(Q38:Z38) -> 13.636566 | Q38: =(Q4+Q16)/Q9 -> 12.315044 | R38: =(R4+R16)/R9 -> 12.819296 | S38: =(S4+S16)/S9 -> 12.946322 | T38: =(T4+T16)/T9 -> 13.259905 | U38: =(U4+U16)/U9 -> 13.63632 | V38: =(V4+V16)/V9 -> 13.897192 | W38: =(W4+W16)/W9 -> 14.137493 | X38: =(X4+X16)/X9 -> 14.376283 | ... AB38: =(AB4+AB16)/AB9 -> 14.75495 | AD38: =AVERAGE(AE38:AN38) -> 15.155588 | AE38: =(AE4+AE16)/AE9 -> 14.850149 | AF38: =(AF4+AF16)/AF9 -> 14.961833 | AG38: =(AG4+AG16)/AG9 -> 15.015509 | AH38: =(AH4+AH16)/AH9 -> 15.078949 | AI38: =(AI4+AI16)/AI9 -> 15.154657 | AJ38: =(AJ4+AJ16)/AJ9 -> 15.179887 | AK38: =(AK4+AK16)/AK9 -> 15.265756 | AL38: =(AL4+AL16)/AL9 -> 15.305694 | ... AP38: =(AP4+AP16)/AP9 -> 15.474847
B40: Brutto Marge | D40: =AVERAGE(E40:N40) -> 0.27001116 | E40: ='Rentabilität'!C19 -> 0.28 | F40: ='Rentabilität'!D19 -> 0.28 | G40: ='Rentabilität'!E19 -> 0.14666667 | H40: ='Rentabilität'!F19 -> -0.093333333 | I40: ='Rentabilität'!G19 -> 0.34567164 | J40: ='Rentabilität'!H19 -> 0.30750716 | K40: ='Rentabilität'!I19 -> 0.29308204 | L40: ='Rentabilität'!J19 -> 0.33954364 | ... N40: ='Rentabilität'!L19 -> 0.4095415 | P40: =AVERAGE(Q40:Z40) -> 0.46905678 | Q40: ='Rentabilität'!M19 -> 0.42233687 | R40: ='Rentabilität'!N19 -> 0.4385833 | S40: ='Rentabilität'!O19 -> 0.44611546 | T40: ='Rentabilität'!P19 -> 0.45697547 | U40: ='Rentabilität'!Q19 -> 0.4682159 | V40: ='Rentabilität'!R19 -> 0.47749368 | W40: ='Rentabilität'!S19 -> 0.48677322 | X40: ='Rentabilität'!T19 -> 0.49450633 | ... AB40: ='Rentabilität'!X19 -> 0.50912456 | AD40: =AVERAGE(AE40:AN40) -> 0.52326673 | AE40: ='Rentabilität'!Y19 -> 0.51248171 | AF40: ='Rentabilität'!Z19 -> 0.51573353 | AG40: ='Rentabilität'!AA19 -> 0.5180392 | AH40: ='Rentabilität'!AB19 -> 0.52061637 | AI40: ='Rentabilität'!AC19 -> 0.52304513 | AJ40: ='Rentabilität'!AD19 -> 0.52473684 | AK40: ='Rentabilität'!AE19 -> 0.52706514 | AL40: ='Rentabilität'!AF19 -> 0.52873487 | ... AP40: ='Rentabilität'!AJ19 -> 0.53452287
B41: Fixkostenquote | D41: n/a | E41: ='Rentabilität'!C20 -> 189.76667 | F41: ='Rentabilität'!D20 -> 55.85 | G41: ='Rentabilität'!E20 -> 26.122222 | H41: ='Rentabilität'!F20 -> 16.993333 | I41: ='Rentabilität'!G20 -> 3.8641791 | J41: ='Rentabilität'!H20 -> 2.6638013 | K41: ='Rentabilität'!I20 -> 1.712306 | L41: ='Rentabilität'!J20 -> 1.4809851 | ... N41: ='Rentabilität'!L20 -> 0.59760108 | P41: =AVERAGE(Q41:Z41) -> 0.25496744 | Q41: ='Rentabilität'!M20 -> 0.46874052 | R41: ='Rentabilität'!N20 -> 0.37212384 | S41: ='Rentabilität'!O20 -> 0.44865828 | T41: ='Rentabilität'!P20 -> 0.33552146 | U41: ='Rentabilität'!Q20 -> 0.21212745 | V41: ='Rentabilität'!R20 -> 0.18173795 | W41: ='Rentabilität'!S20 -> 0.15874403 | X41: ='Rentabilität'!T20 -> 0.13907523 | ... AB41: ='Rentabilität'!X20 -> 0.087943061 | AD41: =AVERAGE(AE41:AN41) -> 0.059309322 | AE41: ='Rentabilität'!Y20 -> 0.08958788 | AF41: ='Rentabilität'!Z20 -> 0.076395986 | AG41: ='Rentabilität'!AA20 -> 0.078969648 | AH41: ='Rentabilität'!AB20 -> 0.07895804 | AI41: ='Rentabilität'!AC20 -> 0.054561512 | AJ41: ='Rentabilität'!AD20 -> 0.050178687 | AK41: ='Rentabilität'!AE20 -> 0.046089344 | AL41: ='Rentabilität'!AF20 -> 0.042547623 | ... AP41: ='Rentabilität'!AJ20 -> 0.031455891
B42: Operative Marge | D42: n/a | E42: ='Rentabilität'!C21 -> -189.48667 | F42: ='Rentabilität'!D21 -> -55.57 | G42: ='Rentabilität'!E21 -> -25.975556 | H42: ='Rentabilität'!F21 -> -17.086667 | I42: ='Rentabilität'!G21 -> -3.5185075 | J42: ='Rentabilität'!H21 -> -2.3562942 | K42: ='Rentabilität'!I21 -> -1.4192239 | L42: ='Rentabilität'!J21 -> -1.1414415 | ... N42: ='Rentabilität'!L21 -> -0.18805959 | P42: =AVERAGE(Q42:Z42) -> 0.21408934 | Q42: ='Rentabilität'!M21 -> -0.046403642 | R42: ='Rentabilität'!N21 -> 0.066459463 | S42: ='Rentabilität'!O21 -> -0.002542826 | T42: ='Rentabilität'!P21 -> 0.12145401 | U42: ='Rentabilität'!Q21 -> 0.25608845 | V42: ='Rentabilität'!R21 -> 0.29575572 | W42: ='Rentabilität'!S21 -> 0.32802919 | X42: ='Rentabilität'!T21 -> 0.35543109 | ... AB42: ='Rentabilität'!X21 -> 0.42118149 | AD42: =AVERAGE(AE42:AN42) -> 0.46395741 | AE42: ='Rentabilität'!Y21 -> 0.42289382 | AF42: ='Rentabilität'!Z21 -> 0.43933755 | AG42: ='Rentabilität'!AA21 -> 0.43906955 | AH42: ='Rentabilität'!AB21 -> 0.44165833 | AI42: ='Rentabilität'!AC21 -> 0.46848362 | AJ42: ='Rentabilität'!AD21 -> 0.47455815 | AK42: ='Rentabilität'!AE21 -> 0.4809758 | AL42: ='Rentabilität'!AF21 -> 0.48618724 | ... AP42: ='Rentabilität'!AJ21 -> 0.50306697
B44: Fixkosten / Bruttomarge - Break-even-Umsatz | E44: ='Rentabilität'!C22 -> 10166.071 | F44: ='Rentabilität'!D22 -> 5983.9286 | G44: ='Rentabilität'!E22 -> 8014.7727 | H44: ='Rentabilität'!F22 -> -13655.357 | I44: ='Rentabilität'!G22 -> 3744.8834 | J44: ='Rentabilität'!H22 -> 4534.8537 | K44: ='Rentabilität'!I22 -> 5269.8555 | L44: ='Rentabilität'!J22 -> 6021.3173 | ... N44: ='Rentabilität'!L22 -> 3771.2906 | Q44: ='Rentabilität'!M22 -> 3657.0333 | R44: ='Rentabilität'!N22 -> 3521.5659 | S44: ='Rentabilität'!O22 -> 5078.2818 | T44: ='Rentabilität'!P22 -> 4473.982 | U44: ='Rentabilität'!Q22 -> 3298.6919 | V44: ='Rentabilität'!R22 -> 3234.5978 | W44: ='Rentabilität'!S22 -> 3172.9355 | X44: ='Rentabilität'!T22 -> 3123.317 | ... AB44: ='Rentabilität'!X22 -> 3033.6388 | AE44: ='Rentabilität'!Y22 -> 3404.024 | AF44: ='Rentabilität'!Z22 -> 3188.6622 | AG44: ='Rentabilität'!AA22 -> 3601.0788 | AH44: ='Rentabilität'!AB22 -> 3927.0759 | AI44: ='Rentabilität'!AC22 -> 2952.9001 | AJ44: ='Rentabilität'!AD22 -> 2943.3801 | AK44: ='Rentabilität'!AE22 -> 2930.3778 | AL44: ='Rentabilität'!AF22 -> 2921.1238 | ... AP44: ='Rentabilität'!AJ22 -> 2889.4928
B46: Monatliches Wachstum (ab 1000 Euro Umsatz) | E46: n/a | F46: =IF(F4>1000,(F4/E4)-1,"n/a") -> n/a | G46: =IF(G4>1000,(G4/F4)-1,"n/a") -> n/a | H46: =IF(H4>1000,(H4/G4)-1,"n/a") -> n/a | I46: =IF(I4>1000,(I4/H4)-1,"n/a") -> n/a | J46: =IF(J4>1000,(J4/I4)-1,"n/a") -> n/a | K46: =IF(K4>1000,(K4/J4)-1,"n/a") -> n/a | L46: =IF(L4>1000,(L4/K4)-1,"n/a") -> 0.5304878 | M46: =IF(M4>1000,(M4/L4)-1,"n/a") -> 0.37812387 | N46: =IF(N4>1000,(N4/M4)-1,"n/a") -> 0.35847569 | Q46: =(Q4/N4)-1 -> 0.27490811 | R46: =(R4/Q4)-1 -> 0.25963581 | S46: =(S4/R4)-1 -> 0.21660041 | T46: =(T4/S4)-1 -> 0.20675314 | U46: =(U4/T4)-1 -> 0.19487979 | V46: =(V4/U4)-1 -> 0.16721604 | W46: =(W4/V4)-1 -> 0.14484909 | X46: =(X4/W4)-1 -> 0.14142556 | Y46: =(Y4/X4)-1 -> 0.12781955 | ... AB46: =(AB4/AA4)-1 -> 0.11183211 | AE46: =(AE4/AB4)-1 -> 0.10875445 | AF46: =(AF4/AE4)-1 -> 0.10545641 | AG46: =(AG4/AF4)-1 -> 0.097417077 | AH46: =(AH4/AG4)-1 -> 0.096113957 | AI46: =(AI4/AH4)-1 -> 0.09322803 | AJ46: =(AJ4/AI4)-1 -> 0.087344343 | AK46: =(AK4/AJ4)-1 -> 0.088726446 | AL46: =(AL4/AK4)-1 -> 0.083241324 | AM46: =(AM4/AL4)-1 -> 0.081211003 | ... AP46: =(AP4/AO4)-1 -> 0.075621324
B47: Jährliches Wachstum | F47: =IFERROR((1+F46)^12-1,"n/a") -> n/a | G47: =IFERROR((1+G46)^12-1,"n/a") -> n/a | H47: =IFERROR((1+H46)^12-1,"n/a") -> n/a | I47: =IFERROR((1+I46)^12-1,"n/a") -> n/a | J47: =IFERROR((1+J46)^12-1,"n/a") -> n/a | K47: =IFERROR((1+K46)^12-1,"n/a") -> n/a | L47: =IFERROR((1+L46)^12-1,"n/a") -> 164.18039 | M47: =IFERROR((1+M46)^12-1,"n/a") -> 45.930918 | N47: =IFERROR((1+N46)^12-1,"n/a") -> 38.502306 | Q47: =(1+Q46)^12-1 -> 17.439392 | R47: =(1+R46)^12-1 -> 14.956587 | S47: =(1+S46)^12-1 -> 9.5141822 | T47: =(1+T46)^12-1 -> 8.5372083 | U47: =(1+U46)^12-1 -> 7.47014 | V47: =(1+V46)^12-1 -> 5.3946234 | W47: =(1+W46)^12-1 -> 4.069661 | X47: =(1+X46)^12-1 -> 3.8907012 | ... AB47: =(1+AB46)^12-1 -> 2.5683755 | AE47: =(1+AE46)^12-1 -> 2.4516321 | AF47: =(1+AF46)^12-1 -> 2.3304236 | AG47: =(1+AG46)^12-1 -> 2.051129 | AH47: =(1+AH46)^12-1 -> 2.0079353 | AI47: =(1+AI46)^12-1 -> 1.9142654 | AJ47: =(1+AJ46)^12-1 -> 1.7315251 | AK47: =(1+AK46)^12-1 -> 1.7734815 | AL47: =(1+AL46)^12-1 -> 1.6103734 | ... AP47: =(1+AP46)^12-1 -> 1.3983515
B48: 40 Regel für SAAS Firmen | F48: =IFERROR(F42+F46,"n/a") -> n/a | G48: =IFERROR(G42+G46,"n/a") -> n/a | H48: =IFERROR(H42+H46,"n/a") -> n/a | I48: =IFERROR(I42+I46,"n/a") -> n/a | J48: =IFERROR(J42+J46,"n/a") -> n/a | K48: =IFERROR(K42+K46,"n/a") -> n/a | L48: =IFERROR(L42+L46,"n/a") -> -0.6109537 | M48: =IFERROR(M42+M46,"n/a") -> -0.04227035 | N48: =IFERROR(N42+N46,"n/a") -> 0.1704161 | Q48: =Q42+Q46 -> 0.22850446 | R48: =R42+R46 -> 0.32609527 | S48: =S42+S46 -> 0.21405758 | T48: =T42+T46 -> 0.32820715 | U48: =U42+U46 -> 0.45096824 | V48: =V42+V46 -> 0.46297176 | W48: =W42+W46 -> 0.47287828 | X48: =X42+X46 -> 0.49685665 | ... AB48: =AB42+AB46 -> 0.5330136 | AE48: =AE42+AE46 -> 0.53164827 | AF48: =AF42+AF46 -> 0.54479396 | AG48: =AG42+AG46 -> 0.53648663 | AH48: =AH42+AH46 -> 0.53777229 | AI48: =AI42+AI46 -> 0.56171165 | AJ48: =AJ42+AJ46 -> 0.5619025 | AK48: =AK42+AK46 -> 0.56970224 | AL48: =AL42+AL46 -> 0.56942857 | ... AP48: =AP42+AP46 -> 0.5786883
A50: Inputs
A51: Calculations
A52: Outputs
A54: Warnings

Sheet Umsatz
A1: Monat | D1: 46112 | E1: =EOMONTH(D1,1) -> 46142 | F1: =EOMONTH(E1,1) -> 46173 | G1: =EOMONTH(F1,1) -> 46203 | H1: =EOMONTH(G1,1) -> 46234 | I1: =EOMONTH(H1,1) -> 46265 | J1: =EOMONTH(I1,1) -> 46295 | K1: =EOMONTH(J1,1) -> 46326 | L1: =EOMONTH(K1,1) -> 46356 | ... AK1: =EOMONTH(AJ1,1) -> 47118
A3: Total Revenue | D3: =D5+D43 -> 15 | E3: =E5+E43 -> 30 | F3: =F5+F43 -> 45 | G3: =G5+G43 -> 75 | H3: =H5+H43 -> 335 | I3: =I5+I43 -> 523.5 | J3: =J5+J43 -> 902 | K3: =K5+K43 -> 1380.5 | ... AK3: =AK5+AK43 -> 49100.5
A5: Digital Service Revenue | D5: =SUM(D18,D38) -> 15 | E5: =SUM(E18,E38) -> 30 | F5: =SUM(F18,F38) -> 45 | G5: =SUM(G18,G38) -> 75 | H5: =SUM(H18,H38) -> 335 | I5: =SUM(I18,I38) -> 523.5 | J5: =SUM(J18,J38) -> 902 | K5: =SUM(K18,K38) -> 1380.5 | ... AK5: =SUM(AK18,AK38) -> 49100.5
B7: Freemium Users | D7: 0 | E7: 0 | F7: 0 | G7: 0 | H7: 0 | I7: 0 | J7: 0 | K7: 0 | L7: 0 | M7: 0 | N7: 0 | O7: 0 | P7: 0 | Q7: 0 | R7: 0 | S7: 0 | T7: 0 | U7: 0 | V7: 0 | W7: 0 | X7: 0 | Y7: 0 | Z7: 0 | AA7: 0 | AB7: 0 | AC7: 0 | AD7: 0 | AE7: 0 | AF7: 0 | AG7: 0 | AH7: 0 | AI7: 0 | AJ7: 0 | AK7: 0
B8: # new users (aus Wachstum) | D8: =Wachstum!E4 -> 3 | E8: =Wachstum!F4 -> 3 | F8: =Wachstum!G4 -> 9 | G8: =Wachstum!H4 -> 20 | H8: =Wachstum!I4 -> 41 | I8: =Wachstum!J4 -> 64 | J8: =Wachstum!K4 -> 123 | K8: =Wachstum!L4 -> 132 | ... AK8: =Wachstum!AL4 -> 2209
B9: # users total | D9: =D8 -> 3 | E9: =D9+E8 -> 6 | F9: =E9+F8 -> 15 | G9: =F9+G8 -> 35 | H9: =G9+H8 -> 76 | I9: =H9+I8 -> 140 | J9: =I9+J8 -> 263 | K9: =J9+K8 -> 395 | L9: =K9+L8 -> 565 | ... AK9: =AJ9+AK8 -> 26135
B10: # active freemium creating cost | D10: =D8 -> 3 | E10: =SUM(D8:E8) -> 6 | F10: =SUM(E8:F8) -> 12 | G10: =SUM(F8:G8) -> 29 | H10: =SUM(G8:H8) -> 61 | I10: =SUM(H8:I8) -> 105 | J10: =SUM(I8:J8) -> 187 | K10: =SUM(J8:K8) -> 255 | L10: =SUM(K8:L8) -> 302 | ... AK10: =SUM(AJ8:AK8) -> 4279
B12: Anteil Nutzer mit Abonnement | C12: 0.1
B13: # users paid new | D13: 1 | E13: 1 | F13: 1 | G13: =ROUND($C12*G8,0) -> 2 | H13: =ROUND($C12*H8,0) -> 4 | I13: =ROUND($C12*I8,0) -> 6 | J13: =ROUND($C12*J8,0) -> 12 | K13: =ROUND($C12*K8,0) -> 13 | L13: =ROUND($C12*L8,0) -> 17 | M13: =ROUND($C12*M8,0) -> 22 | N13: =ROUND($C12*N8,0) -> 26 | ... AK13: =ROUND($C12*AK8,0) -> 221
B14: Monthly Churn | C14: 0.1
B15: # churning in month | D15: 0 | E15: =TRUNC($C14*D16) -> 0 | F15: =TRUNC($C14*E16) -> 0 | G15: =TRUNC($C14*F16) -> 0 | H15: =TRUNC($C14*G16) -> 0 | I15: =TRUNC($C14*H16) -> 0 | J15: =TRUNC($C14*I16) -> 1 | K15: =TRUNC($C14*J16) -> 2 | L15: =TRUNC($C14*K16) -> 3 | ... AK15: =TRUNC($C14*AJ16) -> 131
B16: # users paid total end of month | D16: =D13 -> 1 | E16: =E13+D16 -> 2 | F16: =F13+E16-E15 -> 3 | G16: =G13+F16-F15 -> 5 | H16: =H13+G16-G15 -> 9 | I16: =I13+H16-H15 -> 15 | J16: =J13+I16-I15 -> 27 | K16: =K13+J16-J15 -> 39 | L16: =L13+K16-K15 -> 54 | M16: =M13+L16-L15 -> 73 | ... AK16: =AK13+AJ16-AJ15 -> 1413
B18: Umsatz - Standard Users | D18: =D25+D29 -> 15 | E18: =E25+E29 -> 30 | F18: =F25+F29 -> 45 | G18: =G25+G29 -> 75 | H18: =H25+H29 -> 135 | I18: =I25+I29 -> 223.5 | J18: =J25+J29 -> 402 | K18: =K25+K29 -> 580.5 | ... AK18: =AK25+AK29 -> 20800.5
B19: Preis Standard User | C19: 15
B20: Discount für Jahreabo | C20: 0.1
B21: % Anteil User mit Jahresabo | C21: 0.1
B23: #users Monats abo - neu | D23: =ROUND(D13*(1-$C21),0) -> 1 | E23: =ROUND(E13*(1-$C21),0) -> 1 | F23: =ROUND(F13*(1-$C21),0) -> 1 | G23: =ROUND(G13*(1-$C21),0) -> 2 | H23: =ROUND(H13*(1-$C21),0) -> 4 | I23: =ROUND(I13*(1-$C21),0) -> 5 | J23: =ROUND(J13*(1-$C21),0) -> 11 | K23: =ROUND(K13*(1-$C21),0) -> 12 | ... AK23: =ROUND(AK13*(1-$C21),0) -> 199
B24: #users Monat abo - gesamt | D24: =D23 -> 1 | E24: =E23+D24-D15 -> 2 | F24: =F23+E24-E15 -> 3 | G24: =G23+F24-F15 -> 5 | H24: =H23+G24-G15 -> 9 | I24: =I23+H24-H15 -> 14 | J24: =J23+I24-I15 -> 25 | K24: =K23+J24-J15 -> 36 | L24: =L23+K24-K15 -> 49 | ... AK24: =AK23+AJ24-AJ15 -> 1150
B25: Umsatz monats abo | D25: =D24*$C19 -> 15 | E25: =E24*$C19 -> 30 | F25: =F24*$C19 -> 45 | G25: =G24*$C19 -> 75 | H25: =H24*$C19 -> 135 | I25: =I24*$C19 -> 210 | J25: =J24*$C19 -> 375 | K25: =K24*$C19 -> 540 | ... AK25: =AK24*$C19 -> 17250
B27: # users Jahres abo - neu | D27: =ROUND(D13*$C21-0.1,0) -> 0 | E27: =ROUND(E13*$C21-0.1,0) -> 0 | F27: =ROUND(F13*$C21-0.1,0) -> 0 | G27: =ROUND(G13*$C21-0.1,0) -> 0 | H27: =ROUND(H13*$C21-0.1,0) -> 0 | I27: =ROUND(I13*$C21-0.1,0) -> 1 | J27: =ROUND(J13*$C21-0.1,0) -> 1 | K27: =ROUND(K13*$C21-0.1,0) -> 1 | ... AK27: =ROUND(AK13*$C21-0.1,0) -> 22
B28: # users Jahres abo - gesamt | D28: =D27 -> 0 | E28: =D28+E27 -> 0 | F28: =E28+F27 -> 0 | G28: =F28+G27 -> 0 | H28: =G28+H27 -> 0 | I28: =H28+I27 -> 1 | J28: =I28+J27 -> 2 | K28: =J28+K27 -> 3 | L28: =K28+L27 -> 5 | ... AK28: =AJ28+AK27 -> 263
B29: Revenue yearly subscribers | C29: ohne churn | D29: =D28*$C19*(1-$C21) -> 0 | E29: =E28*$C19*(1-$C21) -> 0 | F29: =F28*$C19*(1-$C21) -> 0 | G29: =G28*$C19*(1-$C21) -> 0 | H29: =H28*$C19*(1-$C21) -> 0 | I29: =I28*$C19*(1-$C21) -> 13.5 | J29: =J28*$C19*(1-$C21) -> 27 | K29: =K28*$C19*(1-$C21) -> 40.5 | ... AK29: =AK28*$C19*(1-$C21) -> 3550.5
B31: PRÜFWERT #total users calculated | D31: =D28+D24 -> 1 | E31: =E28+E24 -> 2 | F31: =F28+F24 -> 3 | G31: =G28+G24 -> 5 | H31: =H28+H24 -> 9 | I31: =I28+I24 -> 15 | J31: =J28+J24 -> 27 | K31: =K28+K24 -> 39 | ... AK31: =AK28+AK24 -> 1413
B33: Zahlungsfluss Monats Abo | D33: =$C19*D24 -> 15 | E33: =$C19*E24 -> 30 | F33: =$C19*F24 -> 45 | G33: =$C19*G24 -> 75 | H33: =$C19*H24 -> 135 | I33: =$C19*I24 -> 210 | J33: =$C19*J24 -> 375 | K33: =$C19*K24 -> 540 | ... AK33: =$C19*AK24 -> 17250
B34: Zahlungsfluss Jahres Abo | D34: =$C19*12*D27*(1-$C20) -> 0 | E34: =$C19*12*E27*(1-$C20) -> 0 | F34: =$C19*12*F27*(1-$C20) -> 0 | G34: =$C19*12*G27*(1-$C20) -> 0 | H34: =$C19*12*H27*(1-$C20) -> 0 | I34: =$C19*12*I27*(1-$C20) -> 162 | J34: =$C19*12*J27*(1-$C20) -> 162 | K34: =$C19*12*K27*(1-$C20) -> 162 | ... O34: =$C19*12*O27*(1-$C20) -> 486 | P34: =$C19*12*P27*(1-$C20)+D34 -> 648 | Q34: =$C19*12*Q27*(1-$C20)+E34 -> 648 | R34: =$C19*12*R27*(1-$C20)+F34 -> 810 | S34: =$C19*12*S27*(1-$C20)+G34 -> 810 | T34: =$C19*12*T27*(1-$C20)+H34 -> 972 | U34: =$C19*12*U27*(1-$C20)+I34 -> 1134 | V34: =$C19*12*V27*(1-$C20)+J34 -> 1296 | W34: =$C19*12*W27*(1-$C20)+K34 -> 1458 | ... AK34: =$C19*12*AK27*(1-$C20)+Y34 -> 5346
B36: COST | D36: =Kosten!E9 -> 3.75 | E36: =Kosten!F9 -> 7.5 | F36: =Kosten!G9 -> 11.25 | G36: =Kosten!H9 -> 18.75 | H36: =Kosten!I9 -> 33.75 | I36: =Kosten!J9 -> 55.875 | J36: =Kosten!K9 -> 100.5 | K36: =Kosten!L9 -> 145.125 | ... AK36: =Kosten!AL9 -> 5200.125
B38: Umsatz - Premium Users | D38: =D40*$C39 -> 0 | E38: =E40*$C39 -> 0 | F38: =F40*$C39 -> 0 | G38: =G40*$C39 -> 0 | H38: =H40*$C39 -> 200 | I38: =I40*$C39 -> 300 | J38: =J40*$C39 -> 500 | K38: =K40*$C39 -> 800 | ... AK38: =AK40*$C39 -> 28300
B39: Umsatz Premium User | C39: 100
B40: #users premium | D40: =ROUND(D16*$C41,0) -> 0 | E40: =ROUND(E16*$C41,0) -> 0 | F40: 0 | G40: 0 | H40: =ROUND(H16*$C41,0) -> 2 | I40: =ROUND(I16*$C41,0) -> 3 | J40: =ROUND(J16*$C41,0) -> 5 | K40: =ROUND(K16*$C41,0) -> 8 | L40: =ROUND(L16*$C41,0) -> 11 | M40: =ROUND(M16*$C41,0) -> 15 | N40: =ROUND(N16*$C41,0) -> 19 | O40: =ROUND(O16*$C41,0) -> 24 | ... AK40: =ROUND(AK16*$C41,0) -> 283
B41: Share of paid users with premium | C41: 0.2
A43: Consulting Revenue | D43: =$C45*D46 -> 0 | E43: =$C45*E46 -> 0 | F43: =$C45*F46 -> 0 | G43: =$C45*G46 -> 0 | H43: =$C45*H46 -> 0 | I43: =$C45*I46 -> 0 | J43: =$C45*J46 -> 0 | K43: =$C45*K46 -> 0 | ... AK43: =$C45*AK46 -> 0
A45: Day Rate | C45: 1500
A46: # Paid days / month | D46: 0 | E46: 0 | F46: 0 | G46: 0 | H46: 0 | I46: 0 | J46: 0 | K46: 0 | L46: 0 | M46: 0 | N46: 0 | O46: 0 | P46: 0 | Q46: 0 | R46: 0 | S46: 0 | T46: 0 | U46: 0 | V46: 0 | W46: 0 | X46: 0 | Y46: 0 | Z46: 0 | AA46: 0 | AB46: 0 | AC46: 0 | AD46: 0 | AE46: 0 | AF46: 0 | AG46: 0 | AH46: 0 | AI46: 0 | AJ46: 0 | AK46: 0
A1005: Revenue

Sheet Wachstum
E1: 46112 | F1: =EOMONTH(E1,1) -> 46142 | G1: =EOMONTH(F1,1) -> 46173 | H1: =EOMONTH(G1,1) -> 46203 | I1: =EOMONTH(H1,1) -> 46234 | J1: =EOMONTH(I1,1) -> 46265 | K1: =EOMONTH(J1,1) -> 46295 | L1: =EOMONTH(K1,1) -> 46326 | M1: =EOMONTH(L1,1) -> 46356 | ... AL1: =EOMONTH(AK1,1) -> 47118
A2: Monat # | E2: 1 | F2: 2 | G2: 3 | H2: 4 | I2: 5 | J2: 6 | K2: 7 | L2: 8 | M2: 9 | N2: 10 | O2: 11 | P2: 12 | Q2: 13 | R2: 14 | S2: 15 | T2: 16 | U2: 17 | V2: 18 | W2: 19 | X2: 20 | Y2: 21 | Z2: 22 | AA2: 23 | AB2: 24 | AC2: 25 | AD2: 26 | AE2: 27 | AF2: 28 | AG2: 29 | AH2: 30 | AI2: 31 | AJ2: 32 | AK2: 33 | AL2: 34
A4: Total - Product Qualified Lead (Neu) | E4: =SUM(E55,E24,E10,E61,E69,E73,E28,E32,E65,E19,E40,E36) -> 3 | F4: =SUM(F55,F24,F10,F61,F69,F73,F28,F32,F65,F19,F40,F36) -> 3 | G4: =SUM(G55,G24,G10,G61,G69,G73,G28,G32,G65,G19,G40,G36) -> 9 | H4: =SUM(H55,H24,H10,H61,H69,H73,H28,H32,H65,H19,H40,H36) -> 20 | I4: =SUM(I55,I24,I10,I61,I69,I73,I28,I32,I65,I19,I40,I36) -> 41 | J4: =SUM(J55,J24,J10,J61,J69,J73,J28,J32,J65,J19,J40,J36) -> 64 | K4: =SUM(K55,K24,K10,K61,K69,K73,K28,K32,K65,K19,K40,K36) -> 123 | L4: =SUM(L55,L24,L10,L61,L69,L73,L28,L32,L65,L19,L40,L36) -> 132 | ... AL4: =SUM(AL55,AL24,AL10,AL61,AL69,AL73,AL28,AL32,AL65,AL19,AL40,AL36) -> 2209
A5: Total - Product Qualified Lead (Kumuliert) | E5: =SUM(E56,E25,E11,E62,E70,E74,E29,E33,E66,E20,E41) -> 3 | F5: =SUM(F56,F25,F11,F62,F70,F74,F29,F33,F66,F20,F41) -> 6 | G5: =SUM(G56,G25,G11,G62,G70,G74,G29,G33,G66,G20,G41) -> 15 | H5: =SUM(H56,H25,H11,H62,H70,H74,H29,H33,H66,H20,H41) -> 35 | I5: =SUM(I56,I25,I11,I62,I70,I74,I29,I33,I66,I20,I41) -> 76 | J5: =SUM(J56,J25,J11,J62,J70,J74,J29,J33,J66,J20,J41) -> 135 | K5: =SUM(K56,K25,K11,K62,K70,K74,K29,K33,K66,K20,K41) -> 248 | L5: =SUM(L56,L25,L11,L62,L70,L74,L29,L33,L66,L20,L41) -> 370 | ... AL5: =SUM(AL56,AL25,AL11,AL62,AL70,AL74,AL29,AL33,AL66,AL20,AL41) -> 25850
A7: Personal
B9: Persönlicher Kontakt und Events
C10: Neu | E10: 3 | F10: 3 | G10: 3 | H10: 3 | I10: 3 | J10: 3 | K10: 3 | L10: 3 | M10: 3 | N10: 3 | O10: 3 | P10: 3 | Q10: 3 | R10: 3 | S10: 3 | T10: 3 | U10: 3 | V10: 3 | W10: 3 | X10: 3 | Y10: 3 | Z10: 3 | AA10: 3 | AB10: 3 | AC10: 3 | AD10: 3 | AE10: 3 | AF10: 3 | AG10: 3 | AH10: 3 | AI10: 3 | AJ10: 3 | AK10: 3 | AL10: 3
C11: Kummuliert | E11: =E10 -> 3 | F11: =F10+E11 -> 6 | G11: =G10+F11 -> 9 | H11: =H10+G11 -> 12 | I11: =I10+H11 -> 15 | J11: =J10+I11 -> 18 | K11: =K10+J11 -> 21 | L11: =L10+K11 -> 24 | M11: =M10+L11 -> 27 | ... AL11: =AL10+AK11 -> 102
A13: Social Media
B15: LinkedIn (3500 Kontakte)
C16: Content (Inbound) | E16: 0 | F16: 0 | G16: 0 | H16: 1 | I16: 1 | J16: 1 | K16: 2 | L16: 2 | M16: 2 | N16: 3 | O16: 3 | P16: 5 | Q16: 5 | R16: 5 | S16: 5 | T16: 5 | U16: 5 | V16: 5 | W16: 5 | X16: 5 | Y16: 5 | Z16: 5 | AA16: 5 | AB16: 5 | AC16: 5 | AD16: 5 | AE16: 5 | AF16: 5 | AG16: 5 | AH16: 5 | AI16: 5 | AJ16: 5 | AK16: 5 | AL16: 5
C17: Groups (Inbound) | E17: 0 | F17: 0 | G17: 0 | H17: 1 | I17: 1 | J17: 1 | K17: 2 | L17: 5 | M17: 5 | N17: 8 | O17: 8 | P17: 8 | Q17: 8 | R17: 8 | S17: 8 | T17: 0 | U17: 0 | V17: 0 | W17: 0 | X17: 0 | Y17: 0 | Z17: 0 | AA17: 0 | AB17: 0 | AC17: 0 | AD17: 0 | AE17: 0 | AF17: 0 | AG17: 0 | AH17: 0 | AI17: 0 | AJ17: 0 | AK17: 0 | AL17: 0
C18: DM (Outbound) | E18: 0 | F18: 0 | G18: 0 | H18: 0 | I18: 5 | J18: 3 | K18: 8 | L18: 10 | M18: 15 | N18: 20 | O18: 15 | P18: 15 | Q18: 15 | R18: 15 | S18: 15 | T18: 15 | U18: 0 | V18: 0 | W18: 0 | X18: 0 | Y18: 0 | Z18: 0 | AA18: 0 | AB18: 0 | AC18: 0 | AD18: 0 | AE18: 0 | AF18: 0 | AG18: 0 | AH18: 0 | AI18: 0 | AJ18: 0 | AK18: 0 | AL18: 0
C19: Neu | E19: =SUM(E16:E18) -> 0 | F19: =SUM(F16:F18) -> 0 | G19: =SUM(G16:G18) -> 0 | H19: =SUM(H16:H18) -> 2 | I19: =SUM(I16:I18) -> 7 | J19: =SUM(J16:J18) -> 5 | K19: =SUM(K16:K18) -> 12 | L19: =SUM(L16:L18) -> 17 | ... AL19: =SUM(AL16:AL18) -> 5
C20: Kummuliert | E20: =E19 -> 0 | F20: =F19+E20 -> 0 | G20: =G19+F20 -> 0 | H20: =H19+G20 -> 2 | I20: =I19+H20 -> 9 | J20: =J19+I20 -> 14 | K20: =K19+J20 -> 26 | L20: =L19+K20 -> 43 | M20: =M19+L20 -> 65 | ... AL20: =AL19+AK20 -> 344
B22: WOM Rate (pro Nutzer/Monat) | E22: =$D23 -> 0.05 | F22: =$D23 -> 0.05 | G22: =$D23 -> 0.05 | H22: =$D23 -> 0.05 | I22: =$D23 -> 0.05 | J22: =$D23 -> 0.05 | K22: =$D23 -> 0.05 | L22: =$D23 -> 0.05 | ... AL22: =$D23 -> 0.05
D23: 0.05
C24: WOM – Neue Nutzer | E24: 0 | F24: =ROUND(E5*F22,0) -> 0 | G24: =ROUND(F5*G22,0) -> 0 | H24: =ROUND(G5*H22,0) -> 1 | I24: =ROUND(H5*I22,0) -> 2 | J24: =ROUND(I5*J22,0) -> 4 | K24: =ROUND(J5*K22,0) -> 7 | L24: =ROUND(K5*L22,0) -> 12 | M24: =ROUND(L5*M22,0) -> 19 | ... AL24: =ROUND(AK5*AL22,0) -> 1183
C25: WOM – Kumuliert | E25: =E24 -> 0 | F25: =F24+E25 -> 0 | G25: =G24+F25 -> 0 | H25: =H24+G25 -> 1 | I25: =I24+H25 -> 3 | J25: =J24+I25 -> 7 | K25: =K24+J25 -> 14 | L25: =L24+K25 -> 26 | M25: =M24+L25 -> 45 | ... AL25: =AL24+AK25 -> 10610
B27: Product Hunt
C28: Neu | E28: 0 | F28: 0 | G28: 0 | H28: 0 | I28: 0 | J28: 0 | K28: 25 | L28: 2 | M28: 2 | N28: 2 | O28: 2 | P28: 2 | Q28: 2 | R28: 2 | S28: 2 | T28: 2 | U28: 2 | V28: 2 | W28: 2 | X28: 2 | Y28: 2 | Z28: 2 | AA28: 2 | AB28: 2 | AC28: 2 | AD28: 2 | AE28: 2 | AF28: 2 | AG28: 2 | AH28: 2 | AI28: 2 | AJ28: 2 | AK28: 2 | AL28: 2
C29: Kummuliert | E29: =E28 -> 0 | F29: =F28+E29 -> 0 | G29: =G28+F29 -> 0 | H29: =H28+G29 -> 0 | I29: =I28+H29 -> 0 | J29: =J28+I29 -> 0 | K29: =K28+J29 -> 25 | L29: =L28+K29 -> 27 | M29: =M28+L29 -> 29 | ... AL29: =AL28+AK29 -> 79
B31: SAAS Service Directories
C32: Neu | E32: 0 | F32: 0 | G32: 0 | H32: 0 | I32: 0 | J32: 2 | K32: 2 | L32: 2 | M32: 2 | N32: 2 | O32: 2 | P32: 2 | Q32: 2 | R32: 2 | S32: 2 | T32: 2 | U32: 2 | V32: 2 | W32: 2 | X32: 2 | Y32: 2 | Z32: 2 | AA32: 2 | AB32: 2 | AC32: 2 | AD32: 2 | AE32: 2 | AF32: 2 | AG32: 2 | AH32: 2 | AI32: 2 | AJ32: 2 | AK32: 2 | AL32: 2
C33: Kummuliert | E33: =E32 -> 0 | F33: =F32+E33 -> 0 | G33: =G32+F33 -> 0 | H33: =H32+G33 -> 0 | I33: =I32+H33 -> 0 | J33: =J32+I33 -> 2 | K33: =K32+J33 -> 4 | L33: =L32+K33 -> 6 | M33: =M32+L33 -> 8 | ... AL33: =AL32+AK33 -> 58
B35: Communities / Foren (Reddit, FB, Indiehackers, etc.)
C36: Neu | E36: 0 | F36: 0 | G36: 0 | H36: 0 | I36: 0 | J36: 5 | K36: 10 | L36: 10 | M36: 10 | N36: 10 | O36: 10 | P36: 10 | Q36: 10 | R36: 10 | S36: 10 | T36: 10 | U36: 10 | V36: 10 | W36: 10 | X36: 10 | Y36: 10 | Z36: 10 | AA36: 10 | AB36: 10 | AC36: 10 | AD36: 10 | AE36: 10 | AF36: 10 | AG36: 10 | AH36: 10 | AI36: 10 | AJ36: 10 | AK36: 10 | AL36: 10
C37: Kummuliert | E37: =E36 -> 0 | F37: =F36+E37 -> 0 | G37: =G36+F37 -> 0 | H37: =H36+G37 -> 0 | I37: =I36+H37 -> 0 | J37: =J36+I37 -> 5 | K37: =K36+J37 -> 15 | L37: =L36+K37 -> 25 | M37: =M36+L37 -> 35 | ... AL37: =AL36+AK37 -> 285
B39: Twitter build in public
C40: Neu | E40: 0 | F40: 0 | G40: 1 | H40: 1 | I40: 5 | J40: 5 | K40: 5 | L40: 5 | M40: 5 | N40: 5 | O40: 5 | P40: 5 | Q40: 5 | R40: 5 | S40: 5 | T40: 5 | U40: 5 | V40: 5 | W40: 5 | X40: 5 | Y40: 5 | Z40: 5 | AA40: 5 | AB40: 5 | AC40: 5 | AD40: 5 | AE40: 5 | AF40: 5 | AG40: 5 | AH40: 5 | AI40: 5 | AJ40: 5 | AK40: 5 | AL40: 5
C41: Kummuliert | E41: =E40 -> 0 | F41: =F40+E41 -> 0 | G41: =G40+F41 -> 1 | H41: =H40+G41 -> 2 | I41: =I40+H41 -> 7 | J41: =J40+I41 -> 12 | K41: =K40+J41 -> 17 | L41: =L40+K41 -> 22 | M41: =M40+L41 -> 27 | ... AL41: =AL40+AK41 -> 152
B43: Content / SEO
C44: Articles published (monthly) | E44: 5 | F44: 4 | G44: 4 | H44: 4 | I44: 4 | J44: 4 | K44: 4 | L44: 4 | M44: 4 | N44: 4 | O44: 4 | P44: 4 | Q44: 4 | R44: 4 | S44: 4 | T44: 4 | U44: 4 | V44: 4 | W44: 4 | X44: 4 | Y44: 4 | Z44: 4 | AA44: 4 | AB44: 4 | AC44: 4 | AD44: 4 | AE44: 4 | AF44: 4 | AG44: 4 | AH44: 4 | AI44: 4 | AJ44: 4 | AK44: 4 | AL44: 4
C45: Articles live | E45: =E44 -> 5 | F45: =E45+F44 -> 9 | G45: =F45+G44 -> 13 | H45: =G45+H44 -> 17 | I45: =H45+I44 -> 21 | J45: =I45+J44 -> 25 | K45: =J45+K44 -> 29 | L45: =K45+L44 -> 33 | M45: =L45+M44 -> 37 | ... AL45: =AK45+AL44 -> 137
C47: Monat nach Veröffentlichung | E47: 1 | F47: 2 | G47: 3 | H47: 4 | I47: 5 | J47: 6 | K47: 7 | L47: 8 | M47: 9 | N47: 10 | O47: 11 | P47: 12 | R47: Gilt für jeden Artikel ab Zeitpunkt der Veröffentlichung
C48: Wirksamkeit | E48: 0 | F48: 0 | G48: 0.1 | H48: 0.2 | I48: 0.3 | J48: 0.4 | K48: 0.5 | L48: 0.6 | M48: 0.7 | N48: 0.8 | O48: 0.9 | P48: 1
C50: Effektiv wirksame Artikel | E50: =E45*E48 -> 0 | F50: =E44*F48+F44*E48 -> 0 | G50: =E45*G48+F45*F48+G45*E48 -> 0.5 | H50: =H48*E44+F44*G48 -> 1.4 | I50: =I48*E44+H48*F44+G48*G44 -> 2.7 | J50: =E44*J48+F44*I48+G44*H48+H44*G48 -> 4.4 | K50: =E44*K48+F44*J48+G44*I48+H44*H48+I44*G48 -> 6.5 | L50: =E44*L48+F44*K48+G44*J48+H44*I48+I44*H48+J44*G48 -> 9 | M50: =E44*M48+F44*L48+G44*K48+H44*J48+I44*I48+J44*H48+K44*G48 -> 11.9 | N50: =E44*N48+F44*M48+G44*L48+H44*K48+I44*J48+J44*I48+K44*H48+L44*G48 -> 15.2 | O50: =E44*$O48+F44*$N48+G44*$M48+H44*$L48+I44*$K48+J44*$J48+K44*$I48+L44*$H48+M44*$G48+N44*$F48 -> 18.9 | P50: =E44*P48+F44*O48+G44*N48+H44*M48+I44*L48+J44*K48+K44*J48+L44*I48+M44*H48+N44*G48 -> 23 | Q50: =F45+G44*$E48+H44*$F48+I44*$G48+J44*$H48+K44*$I48+L44*$J48+M44*$K48+N44*$L48+O44*$M48+P44*$N48+Q44*$O48 -> 27 | R50: =G45+H44*$E48+I44*$F48+J44*$G48+K44*$H48+L44*$I48+M44*$J48+N44*$K48+O44*$L48+P44*$M48+Q44*$N48+R44*$O48 -> 31 | S50: =H45+I44*$E48+J44*$F48+K44*$G48+L44*$H48+M44*$I48+N44*$J48+O44*$K48+P44*$L48+Q44*$M48+R44*$N48+S44*$O48 -> 35 | T50: =I45+J44*$E48+K44*$F48+L44*$G48+M44*$H48+N44*$I48+O44*$J48+P44*$K48+Q44*$L48+R44*$M48+S44*$N48+T44*$O48 -> 39 | U50: =J45+K44*$E48+L44*$F48+M44*$G48+N44*$H48+O44*$I48+P44*$J48+Q44*$K48+R44*$L48+S44*$M48+T44*$N48+U44*$O48 -> 43 | V50: =K45+L44*$E48+M44*$F48+N44*$G48+O44*$H48+P44*$I48+Q44*$J48+R44*$K48+S44*$L48+T44*$M48+U44*$N48+V44*$O48 -> 47 | W50: =L45+M44*$E48+N44*$F48+O44*$G48+P44*$H48+Q44*$I48+R44*$J48+S44*$K48+T44*$L48+U44*$M48+V44*$N48+W44*$O48 -> 51 | X50: =M45+N44*$E48+O44*$F48+P44*$G48+Q44*$H48+R44*$I48+S44*$J48+T44*$K48+U44*$L48+V44*$M48+W44*$N48+X44*$O48 -> 55 | ... AL50: =AA45+AB44*$E48+AC44*$F48+AD44*$G48+AE44*$H48+AF44*$I48+AG44*$J48+AH44*$K48+AI44*$L48+AJ44*$M48+AK44*$N48+AL44*$O48 -> 111
C51: Besucher pro Artikel pro Monat | D51: 150
C52: Besucher gesamt | E52: =E50*Wachstum!$D51 -> 0 | F52: =F50*Wachstum!$D51 -> 0 | G52: =G50*Wachstum!$D51 -> 75 | H52: =H50*Wachstum!$D51 -> 210 | I52: =I50*Wachstum!$D51 -> 405 | J52: =J50*Wachstum!$D51 -> 660 | K52: =K50*Wachstum!$D51 -> 975 | L52: =L50*Wachstum!$D51 -> 1350 | ... AL52: =AL50*Wachstum!$D51 -> 16650
C54: Besucher Conversion | D54: 0.06
...

Sheet Kosten
E1: 46112 | F1: =EOMONTH(E1,1) -> 46142 | G1: =EOMONTH(F1,1) -> 46173 | H1: =EOMONTH(G1,1) -> 46203 | I1: =EOMONTH(H1,1) -> 46234 | J1: =EOMONTH(I1,1) -> 46265 | K1: =EOMONTH(J1,1) -> 46295 | L1: =EOMONTH(K1,1) -> 46326 | M1: =EOMONTH(L1,1) -> 46356 | ... AL1: =EOMONTH(AK1,1) -> 47118
A3: Gesamtkosten | E3: =E5+E13 -> -2857.3 | F3: =F5+F13 -> -1697.1 | G3: =G5+G13 -> -1213.9 | H3: =H5+H13 -> -1356.5 | I3: =I5+I13 -> -1513.7 | J3: =J5+J13 -> -1757.02 | K3: =K5+K13 -> -2182.14 | L3: =L5+L13 -> -2956.26 | ... AL3: =AL5+AL13 -> -24399.66
A5: Variable Kosten | E5: =-SUM(E8:E11) -> -10.8 | F5: =-SUM(F8:F11) -> -21.6 | G5: =-SUM(G8:G11) -> -38.4 | H5: =-SUM(H8:H11) -> -82 | I5: =-SUM(I8:I11) -> -219.2 | J5: =-SUM(J8:J11) -> -362.52 | K5: =-SUM(K8:K11) -> -637.64 | L5: =-SUM(L8:L11) -> -911.76 | ... AL5: =-SUM(AL8:AL11) -> -22855.16
B7: Direkte Kosten | D7: pro Nutzer
C8: Kosten von Free Accounts, fixe Kosten pro Account | D8: 2 | E8: =$D8*Umsatz!D10 -> 6 | F8: =$D8*Umsatz!E10 -> 12 | G8: =$D8*Umsatz!F10 -> 24 | H8: =$D8*Umsatz!G10 -> 58 | I8: =$D8*Umsatz!H10 -> 122 | J8: =$D8*Umsatz!I10 -> 210 | K8: =$D8*Umsatz!J10 -> 374 | L8: =$D8*Umsatz!K10 -> 510 | ... AL8: =$D8*Umsatz!AK10 -> 8558
C9: Kosten von Paid Accounts als Prozent vom Verkaufspreis | D9: 0.25 | E9: =Umsatz!D18*$D9 -> 3.75 | F9: =Umsatz!E18*$D9 -> 7.5 | G9: =Umsatz!F18*$D9 -> 11.25 | H9: =Umsatz!G18*$D9 -> 18.75 | I9: =Umsatz!H18*$D9 -> 33.75 | J9: =Umsatz!I18*$D9 -> 55.875 | K9: =Umsatz!J18*$D9 -> 100.5 | L9: =Umsatz!K18*$D9 -> 145.125 | ... AL9: =Umsatz!AK18*$D9 -> 5200.125
C10: Kosten von Premium Accounts als Prozent vom Verkaufspreis | D10: 0.2 | E10: =$D10*Umsatz!D38 -> 0 | F10: =$D10*Umsatz!E38 -> 0 | G10: =$D10*Umsatz!F38 -> 0 | H10: =$D10*Umsatz!G38 -> 0 | I10: =$D10*Umsatz!H38 -> 40 | J10: =$D10*Umsatz!I38 -> 60 | K10: =$D10*Umsatz!J38 -> 100 | L10: =$D10*Umsatz!K38 -> 160 | ... AL10: =$D10*Umsatz!AK38 -> 5660
C11: Verkaufs- & Steuerabwicklungsgebühren (Merchant of Record) | D11: 0.07 | E11: =$D11*Umsatz!D5 -> 1.05 | F11: =$D11*Umsatz!E5 -> 2.1 | G11: =$D11*Umsatz!F5 -> 3.15 | H11: =$D11*Umsatz!G5 -> 5.25 | I11: =$D11*Umsatz!H5 -> 23.45 | J11: =$D11*Umsatz!I5 -> 36.645 | K11: =$D11*Umsatz!J5 -> 63.14 | L11: =$D11*Umsatz!K5 -> 96.635 | ... AL11: =$D11*Umsatz!AK5 -> 3437.035
A13: Fixkosten | E13: =E15+E21+E29+E48+E55+E39 -> -2846.5 | F13: =F15+F21+F29+F48+F55+F39 -> -1675.5 | G13: =G15+G21+G29+G48+G55+G39 -> -1175.5 | H13: =H15+H21+H29+H48+H55+H39 -> -1274.5 | I13: =I15+I21+I29+I48+I55+I39 -> -1294.5 | J13: =J15+J21+J29+J48+J55+J39 -> -1394.5 | K13: =K15+K21+K29+K48+K55+K39 -> -1544.5 | L13: =L15+L21+L29+L48+L55+L39 -> -2044.5 | ... AL13: =AL15+AL21+AL29+AL48+AL55+AL39 -> -1544.5
B15: Produktentwicklung | E15: =-SUM(E16:E20) -> -680 | F15: =-SUM(F16:F20) -> -680 | G15: =-SUM(G16:G20) -> -680 | H15: =-SUM(H16:H20) -> -680 | I15: =-SUM(I16:I20) -> -680 | J15: =-SUM(J16:J20) -> -680 | K15: =-SUM(K16:K20) -> -680 | L15: =-SUM(L16:L20) -> -680 | ... AL15: =-SUM(AL16:AL20) -> -680
C16: Coding Agent: Claude Code | E16: 100 | F16: 100 | G16: 100 | H16: 100 | I16: 100 | J16: 100 | K16: 100 | L16: 100 | M16: 100 | N16: 100 | O16: 100 | P16: 100 | Q16: 100 | R16: 100 | S16: 100 | T16: 100 | U16: 100 | V16: 100 | W16: 100 | X16: 100 | Y16: 100 | Z16: 100 | AA16: 100 | AB16: 100 | AC16: 100 | AD16: 100 | AE16: 100 | AF16: 100 | AG16: 100 | AH16: 100 | AI16: 100 | AJ16: 100 | AK16: 100 | AL16: 100
C17: Coding IDE: Cursor | E17: 60 | F17: 60 | G17: 60 | H17: 60 | I17: 60 | J17: 60 | K17: 60 | L17: 60 | M17: 60 | N17: 60 | O17: 60 | P17: 60 | Q17: 60 | R17: 60 | S17: 60 | T17: 60 | U17: 60 | V17: 60 | W17: 60 | X17: 60 | Y17: 60 | Z17: 60 | AA17: 60 | AB17: 60 | AC17: 60 | AD17: 60 | AE17: 60 | AF17: 60 | AG17: 60 | AH17: 60 | AI17: 60 | AJ17: 60 | AK17: 60 | AL17: 60
C18: KI Protoyping: Lovable | E18: 20 | F18: 20 | G18: 20 | H18: 20 | I18: 20 | J18: 20 | K18: 20 | L18: 20 | M18: 20 | N18: 20 | O18: 20 | P18: 20 | Q18: 20 | R18: 20 | S18: 20 | T18: 20 | U18: 20 | V18: 20 | W18: 20 | X18: 20 | Y18: 20 | Z18: 20 | AA18: 20 | AB18: 20 | AC18: 20 | AD18: 20 | AE18: 20 | AF18: 20 | AG18: 20 | AH18: 20 | AI18: 20 | AJ18: 20 | AK18: 20 | AL18: 20
C19: Rechenleistung für KI Training und Datenbankaufbau | E19: 500 | F19: 500 | G19: 500 | H19: 500 | I19: 500 | J19: 500 | K19: 500 | L19: 500 | M19: 500 | N19: 500 | O19: 500 | P19: 500 | Q19: 500 | R19: 500 | S19: 500 | T19: 500 | U19: 500 | V19: 500 | W19: 500 | X19: 500 | Y19: 500 | Z19: 500 | AA19: 500 | AB19: 500 | AC19: 500 | AD19: 500 | AE19: 500 | AF19: 500 | AG19: 500 | AH19: 500 | AI19: 500 | AJ19: 500 | AK19: 500 | AL19: 500
B21: IT Infrastruktur | E21: =-SUM(E22:E27) -> -203.6 | F21: =-SUM(F22:F27) -> -203.6 | G21: =-SUM(G22:G27) -> -203.6 | H21: =-SUM(H22:H27) -> -203.6 | I21: =-SUM(I22:I27) -> -223.6 | J21: =-SUM(J22:J27) -> -323.6 | K21: =-SUM(K22:K27) -> -323.6 | L21: =-SUM(L22:L27) -> -323.6 | ... AL21: =-SUM(AL22:AL27) -> -323.6
C22: Email & Office (Google Workspace) | E22: 13.6 | F22: 13.6 | G22: 13.6 | H22: 13.6 | I22: 13.6 | J22: 13.6 | K22: 13.6 | L22: 13.6 | M22: 13.6 | N22: 13.6 | O22: 13.6 | P22: 13.6 | Q22: 13.6 | R22: 13.6 | S22: 13.6 | T22: 13.6 | U22: 13.6 | V22: 13.6 | W22: 13.6 | X22: 13.6 | Y22: 13.6 | Z22: 13.6 | AA22: 13.6 | AB22: 13.6 | AC22: 13.6 | AD22: 13.6 | AE22: 13.6 | AF22: 13.6 | AG22: 13.6 | AH22: 13.6 | AI22: 13.6 | AJ22: 13.6 | AK22: 13.6 | AL22: 13.6
C23: Internet / Telefon anteilig, betrieblich | E23: 50 | F23: 50 | G23: 50 | H23: 50 | I23: 50 | J23: 50 | K23: 50 | L23: 50 | M23: 50 | N23: 50 | O23: 50 | P23: 50 | Q23: 50 | R23: 50 | S23: 50 | T23: 50 | U23: 50 | V23: 50 | W23: 50 | X23: 50 | Y23: 50 | Z23: 50 | AA23: 50 | AB23: 50 | AC23: 50 | AD23: 50 | AE23: 50 | AF23: 50 | AG23: 50 | AH23: 50 | AI23: 50 | AJ23: 50 | AK23: 50 | AL23: 50
C24: Hosting (Hetzner, AWS) | E24: 100 | F24: 100 | G24: 100 | H24: 100 | I24: 100 | J24: 200 | K24: 200 | L24: 200 | M24: 200 | N24: 200 | O24: 200 | P24: 200 | Q24: 200 | R24: 200 | S24: 200 | T24: 200 | U24: 200 | V24: 200 | W24: 200 | X24: 200 | Y24: 200 | Z24: 200 | AA24: 200 | AB24: 200 | AC24: 200 | AD24: 200 | AE24: 200 | AF24: 200 | AG24: 200 | AH24: 200 | AI24: 200 | AJ24: 200 | AK24: 200 | AL24: 200
C25: Sentry (Application Monitoring) | E25: 0 | F25: 0 | G25: 0 | H25: 0 | I25: 20 | J25: 20 | K25: 20 | L25: 20 | M25: 20 | N25: 20 | O25: 20 | P25: 20 | Q25: 20 | R25: 20 | S25: 20 | T25: 20 | U25: 20 | V25: 20 | W25: 20 | X25: 20 | Y25: 20 | Z25: 20 | AA25: 20 | AB25: 20 | AC25: 20 | AD25: 20 | AE25: 20 | AF25: 20 | AG25: 20 | AH25: 20 | AI25: 20 | AJ25: 20 | AK25: 20 | AL25: 20
C26: Quellcode Verwaltung Github | E26: 20 | F26: 20 | G26: 20 | H26: 20 | I26: 20 | J26: 20 | K26: 20 | L26: 20 | M26: 20 | N26: 20 | O26: 20 | P26: 20 | Q26: 20 | R26: 20 | S26: 20 | T26: 20 | U26: 20 | V26: 20 | W26: 20 | X26: 20 | Y26: 20 | Z26: 20 | AA26: 20 | AB26: 20 | AC26: 20 | AD26: 20 | AE26: 20 | AF26: 20 | AG26: 20 | AH26: 20 | AI26: 20 | AJ26: 20 | AK26: 20 | AL26: 20
C27: Email sending | E27: 20 | F27: 20 | G27: 20 | H27: 20 | I27: 20 | J27: 20 | K27: 20 | L27: 20 | M27: 20 | N27: 20 | O27: 20 | P27: 20 | Q27: 20 | R27: 20 | S27: 20 | T27: 20 | U27: 20 | V27: 20 | W27: 20 | X27: 20 | Y27: 20 | Z27: 20 | AA27: 20 | AB27: 20 | AC27: 20 | AD27: 20 | AE27: 20 | AF27: 20 | AG27: 20 | AH27: 20 | AI27: 20 | AJ27: 20 | AK27: 20 | AL27: 20
H28: ´
B29: Administrative Kosten | E29: =-SUM(E30:E37) -> -81.9 | F29: =-SUM(F30:F37) -> -81.9 | G29: =-SUM(G30:G37) -> -81.9 | H29: =-SUM(H30:H37) -> -81.9 | I29: =-SUM(I30:I37) -> -81.9 | J29: =-SUM(J30:J37) -> -81.9 | K29: =-SUM(K30:K37) -> -231.9 | L29: =-SUM(L30:L37) -> -231.9 | ... AL29: =-SUM(AL30:AL37) -> -231.9
C30: Kontoführung | E30: 10 | F30: 10 | G30: 10 | H30: 10 | I30: 10 | J30: 10 | K30: 10 | L30: 10 | M30: 10 | N30: 10 | O30: 10 | P30: 10 | Q30: 10 | R30: 10 | S30: 10 | T30: 10 | U30: 10 | V30: 10 | W30: 10 | X30: 10 | Y30: 10 | Z30: 10 | AA30: 10 | AB30: 10 | AC30: 10 | AD30: 10 | AE30: 10 | AF30: 10 | AG30: 10 | AH30: 10 | AI30: 10 | AJ30: 10 | AK30: 10 | AL30: 10
C31: Steuerberater | R31: 500 | AD31: 500
C32: Datenschutzberatung | Q32: 200 | AA32: 200
C33: Buchhaltung Lexoffice | E33: 21.9 | F33: 21.9 | G33: 21.9 | H33: 21.9 | I33: 21.9 | J33: 21.9 | K33: 21.9 | L33: 21.9 | M33: 21.9 | N33: 21.9 | O33: 21.9 | P33: 21.9 | Q33: 21.9 | R33: 21.9 | S33: 21.9 | T33: 21.9 | U33: 21.9 | V33: 21.9 | W33: 21.9 | X33: 21.9 | Y33: 21.9 | Z33: 21.9 | AA33: 21.9 | AB33: 21.9 | AC33: 21.9 | AD33: 21.9 | AE33: 21.9 | AF33: 21.9 | AG33: 21.9 | AH33: 21.9 | AI33: 21.9 | AJ33: 21.9 | AK33: 21.9 | AL33: 21.9
C34: IHK Beitrag (Befreiung erste 2 Jahre) | G34: 0 | P34: 0 | AB34: 100
C35: Berufshaftpflichtversicherung (exali.de) | Q35: 321 | AC35: 321
C36: Rechtsberatung | Q36: 200
C37: Reisen und Events | E37: 50 | F37: 50 | G37: 50 | H37: 50 | I37: 50 | J37: 50 | K37: 200 | L37: 200 | M37: 200 | N37: 200 | O37: 200 | P37: 200 | Q37: 200 | R37: 200 | S37: 200 | T37: 200 | U37: 200 | V37: 200 | W37: 200 | X37: 200 | Y37: 200 | Z37: 200 | AA37: 200 | AB37: 200 | AC37: 200 | AD37: 200 | AE37: 200 | AF37: 200 | AG37: 200 | AH37: 200 | AI37: 200 | AJ37: 200 | AK37: 200 | AL37: 200
B39: Gründungskosten | E39: =-SUM(E40:E46) -> -1671 | F39: =-SUM(F40:F46) -> -500 | G39: =-SUM(G40:G46) -> 0 | H39: =-SUM(H40:H46) -> 0 | I39: =-SUM(I40:I46) -> 0 | J39: =-SUM(J40:J46) -> 0 | K39: =-SUM(K40:K46) -> 0 | L39: =-SUM(L40:L46) -> -500 | ... AL39: =-SUM(AL40:AL46) -> 0
C40: Markenschutz Deutschland | E40: 290
C41: Markenschutz EU / US
C42: Steuerberater | E42: 500 | L42: 500
C43: Datenschutzberatung für Gründung | F43: 500
C44: Rechtsberatung für Gründung | E44: 500
C45: Berufshaftpflichtversicherung (exali.de) | E45: 321
C46: Gewerbeanmeldung | E46: 60
B48: Marketing Kosten | E48: =-SUM(E49:E53) -> -210 | F48: =-SUM(F49:F53) -> -210 | G48: =-SUM(G49:G53) -> -210 | H48: =-SUM(H49:H53) -> -309 | I48: =-SUM(I49:I53) -> -309 | J48: =-SUM(J49:J53) -> -309 | K48: =-SUM(K49:K53) -> -309 | L48: =-SUM(L49:L53) -> -309 | ... AL48: =-SUM(AL49:AL53) -> -309
...

Sheet Investitionen
A1: Investitionen | D1: Betrag (netto)
A2: Kategorie | B2: Bezeichnung | C2: Herkunft | D2: =SUM(D3) -> 2000
A3: Hardware | B3: Laptop, Apple MacBook Pro 14.2 (Zeitwert) | C3: Sacheinlage | D3: =ROUND(2970.89/1.19*0.8/100,0)*100 -> 2000

Sheet Liquidität
A1: 400 | B1: 400 | C1: 46112 | D1: =EOMONTH(C1,1) -> 46142 | E1: =EOMONTH(D1,1) -> 46173 | F1: =EOMONTH(E1,1) -> 46203 | G1: =EOMONTH(F1,1) -> 46234 | H1: =EOMONTH(G1,1) -> 46265 | I1: =EOMONTH(H1,1) -> 46295 | J1: =EOMONTH(I1,1) -> 46326 | K1: =EOMONTH(J1,1) -> 46356 | ... AJ1: =EOMONTH(AI1,1) -> 47118
A3: Liquide Mittel am Monatsanfang | C3: 0 | D3: =C26 -> 1157.7 | E3: =D26 -> 1490.6 | F3: =E26 -> 2321.7 | G3: =F26 -> 3040.2 | H3: =G26 -> 3861.5 | I3: =H26 -> 3776.48 | J3: =I26 -> 3631.34 | K3: =J26 -> 3177.08 | ... AJ3: =AI26 -> 113996.7
A4: Einzahlungen Brutto | C4: =SUM(C5:C8) -> 4015 | D4: =SUM(D5:D8) -> 2030 | E4: =SUM(E5:E8) -> 2045 | F4: =SUM(F5:F8) -> 2075 | G4: =SUM(G5:G8) -> 2335 | H4: =SUM(H5:H8) -> 1672 | I4: =SUM(I5:I8) -> 2037 | J4: =SUM(J5:J8) -> 2502 | ... AJ4: =SUM(AJ5:AJ8) -> 50896
